Workbook

Sheet DASHBOARD
A1: 📊 ENGLISH CLASS MANAGEMENT — DASHBOARD
A2: All metrics auto-calculate from STUDENTS, ENROLLMENTS & ATTENDANCE_LOG. Yellow cells = inputs you can change.
A4: ▎ SECTION 1 — OVERVIEW
A5: ACTIVE STUDENTS | C5: OVERALL ATTENDANCE RATE | E5: AT RISK | G5: POSSIBLY DROPPED
A6: =COUNTIF(STUDENTS!E:E,"Active") -> 158 | C6: =IFERROR(COUNTIF(ATTENDANCE_LOG!G:G,"Present")/(COUNTIF(ATTENDANCE_LOG!G:G,"Present")+COUNTIF(ATTENDANCE_LOG!G:G,"Absent")),0) -> 0.86467262 | E6: =COUNTIF(#REF!,"⚠ At Risk") -> #REF! | G6: =COUNTIF(STUDENTS!L:L,"⚠ Possibly Dropped") -> 0
A7: =" out of "&(COUNTIF(STUDENTS!E:E,"Active")+COUNTIF(STUDENTS!E:E,"Inactive")+COUNTIF(STUDENTS!E:E,"Waiting for class"))&" total" -> out of 304 total | C7: =COUNTIF(ATTENDANCE_LOG!G:G,"Present")&" / "&(COUNTIF(ATTENDANCE_LOG!G:G,"Present")+COUNTIF(ATTENDANCE_LOG!G:G,"Absent"))&" sessions" -> 4741 / 5483 sessions | E7: flagged for follow-up | G7: inactive > 30 days
A8: INACTIVE | C8: WAITING FOR CLASS
A9: =COUNTIF(STUDENTS!E:E,"Inactive") -> 133 | C9: =COUNTIF(STUDENTS!E:E,"Waiting for class") -> 13
A10: completed or stopped | C10: pending placement
A12: ▎ SECTION 2 — ACTIVE STUDENTS BY COURSE | J12: 304 | K12: =J12/1200 -> 0.25333333
A13: Course Name | B13: Active | C13: Inactive | D13: Waiting | E13: Total | F13: % of Active | G13: Bar | J13: 105 | K13: =J13/1200 -> 0.0875
A14: Communication 1 | B14: =COUNTIFS(STUDENTS!G:G,A14,STUDENTS!E:E,"Active") -> 0 | C14: =COUNTIFS(STUDENTS!G:G,A14,STUDENTS!E:E,"Inactive") -> 0 | D14: =COUNTIFS(STUDENTS!G:G,A14,STUDENTS!E:E,"Waiting for class") -> 0 | E14: =B14+C14+D14 -> 0 | F14: =IFERROR(B14/$B$20,0) -> 0 | G14: =IF($B$20=0,"",REPT("█",ROUND(B14/MAX($B$14:$B$19)*20,0))) | J14: =J12-J13 -> 199 | K14: =J14/1200 -> 0.16583333
A15: Communication 2 | B15: =COUNTIFS(STUDENTS!G:G,A15,STUDENTS!E:E,"Active") -> 0 | C15: =COUNTIFS(STUDENTS!G:G,A15,STUDENTS!E:E,"Inactive") -> 0 | D15: =COUNTIFS(STUDENTS!G:G,A15,STUDENTS!E:E,"Waiting for class") -> 0 | E15: =B15+C15+D15 -> 0 | F15: =IFERROR(B15/$B$20,0) -> 0 | G15: =IF($B$20=0,"",REPT("█",ROUND(B15/MAX($B$14:$B$19)*20,0)))
A16: Communication 3 | B16: =COUNTIFS(STUDENTS!G:G,A16,STUDENTS!E:E,"Active") -> 0 | C16: =COUNTIFS(STUDENTS!G:G,A16,STUDENTS!E:E,"Inactive") -> 0 | D16: =COUNTIFS(STUDENTS!G:G,A16,STUDENTS!E:E,"Waiting for class") -> 0 | E16: =B16+C16+D16 -> 0 | F16: =IFERROR(B16/$B$20,0) -> 0 | G16: =IF($B$20=0,"",REPT("█",ROUND(B16/MAX($B$14:$B$19)*20,0)))
A17: Business English | B17: =COUNTIFS(STUDENTS!G:G,A17,STUDENTS!E:E,"Active") -> 0 | C17: =COUNTIFS(STUDENTS!G:G,A17,STUDENTS!E:E,"Inactive") -> 0 | D17: =COUNTIFS(STUDENTS!G:G,A17,STUDENTS!E:E,"Waiting for class") -> 0 | E17: =B17+C17+D17 -> 0 | F17: =IFERROR(B17/$B$20,0) -> 0 | G17: =IF($B$20=0,"",REPT("█",ROUND(B17/MAX($B$14:$B$19)*20,0)))
A18: Foundation | B18: =COUNTIFS(STUDENTS!G:G,A18,STUDENTS!E:E,"Active") -> 0 | C18: =COUNTIFS(STUDENTS!G:G,A18,STUDENTS!E:E,"Inactive") -> 0 | D18: =COUNTIFS(STUDENTS!G:G,A18,STUDENTS!E:E,"Waiting for class") -> 0 | E18: =B18+C18+D18 -> 0 | F18: =IFERROR(B18/$B$20,0) -> 0 | G18: =IF($B$20=0,"",REPT("█",ROUND(B18/MAX($B$14:$B$19)*20,0)))
A19: Extension of Foundation | B19: =COUNTIFS(STUDENTS!G:G,A19,STUDENTS!E:E,"Active") -> 0 | C19: =COUNTIFS(STUDENTS!G:G,A19,STUDENTS!E:E,"Inactive") -> 0 | D19: =COUNTIFS(STUDENTS!G:G,A19,STUDENTS!E:E,"Waiting for class") -> 0 | E19: =B19+C19+D19 -> 0 | F19: =IFERROR(B19/$B$20,0) -> 0 | G19: =IF($B$20=0,"",REPT("█",ROUND(B19/MAX($B$14:$B$19)*20,0)))
A20: TOTAL | B20: =SUM(B14:B19) -> 0 | C20: =SUM(C14:C19) -> 0 | D20: =SUM(D14:D19) -> 0 | E20: =SUM(E14:E19) -> 0 | F20: =IFERROR(B20/E20,0) -> 0
A22: ▎ SECTION 3 — WHY STUDENTS GO INACTIVE
A23: Drop Reason | B23: Count | C23: % | E23: Inactive Classification | F23: Count | G23: %
A24: High workload | B24: =COUNTIF(STUDENTS!N:N,A24) -> 101 | C24: =IFERROR(B24/SUM($B$24:$B$29),0) -> 0.56424581 | E24: Completed (no continuation) | F24: =COUNTIF(STUDENTS!M:M,E24) -> 95 | G24: =IFERROR(F24/SUM($F$24:$F$27),0) -> 0.53072626
A25: Prefer different learning format | B25: =COUNTIF(STUDENTS!N:N,A25) -> 21 | C25: =IFERROR(B25/SUM($B$24:$B$29),0) -> 0.11731844 | E25: Discontinued mid-course | F25: =COUNTIF(STUDENTS!M:M,E25) -> 82 | G25: =IFERROR(F25/SUM($F$24:$F$27),0) -> 0.45810056
A26: Learning goal achieved | B26: =COUNTIF(STUDENTS!N:N,A26) -> 33 | C26: =IFERROR(B26/SUM($B$24:$B$29),0) -> 0.18435754 | E26: Business EL, chờ xếp lớp | F26: =COUNTIF(STUDENTS!M:M,E26) -> 1 | G26: =IFERROR(F26/SUM($F$24:$F$27),0) -> 0.0055865922
A27: Team restructuring | B27: =COUNTIF(STUDENTS!N:N,A27) -> 5 | C27: =IFERROR(B27/SUM($B$24:$B$29),0) -> 0.027932961 | E27: BE, chờ xếp lớp | F27: =COUNTIF(STUDENTS!M:M,E27) -> 1 | G27: =IFERROR(F27/SUM($F$24:$F$27),0) -> 0.0055865922
A28: Maternity leave | B28: =COUNTIF(STUDENTS!N:N,A28) -> 3 | C28: =IFERROR(B28/SUM($B$24:$B$29),0) -> 0.016759777
A29: Resign | B29: =COUNTIF(STUDENTS!N:N,A29) -> 16 | C29: =IFERROR(B29/SUM($B$24:$B$29),0) -> 0.089385475
A30: TOTAL | B30: =SUM(B24:B29) -> 179 | C30: =SUM(C24:D29) -> 1 | E30: TOTAL | F30: =SUM(F24:F28) -> 179
A32: ▎ SECTION 4 — CLASS PROGRESS
A33: Class Code | B33: Course Name | C33: PIC | D33: Sessions Done | E33: Expected | F33: Progress % | G33: Progress Bar | H33: Status
A34: EL001 | B34: Business English | C34: =IFERROR(VLOOKUP(A34,PIC!A:B,2,0),"") -> Anh Vu | D34: =IFERROR(_xludf.MAXIFS(ATTENDANCE_LOG!E:E,ATTENDANCE_LOG!A:A,A34,ATTENDANCE_LOG!B:B,B34),0) -> 0 | E34: =IFERROR(VLOOKUP(B34,COURSE_PLAN!A:B,2,0),0) -> 16 | F34: =IFERROR(MIN(D34/E34,1),0) -> 0 | G34: =IF(E34=0,"—",REPT("█",ROUND(F34*20,0))&REPT("░",20-ROUND(F34*20,0))) -> ░░░░░░░░░░░░░░░░░░░░ | H34: =IF(E34=0,"No plan",IF(F34>=1,"✅ Done",IF(F34>=0.75,"🟢 Almost",IF(F34>=0.25,"🔄 In progress",IF(F34>0,"🟡 Just started","⚪ Not started"))))) -> ⚪ Not started
A35: EL001 | B35: Communication 1 | C35: =IFERROR(VLOOKUP(A35,PIC!A:B,2,0),"") -> Anh Vu | D35: =IFERROR(_xludf.MAXIFS(ATTENDANCE_LOG!E:E,ATTENDANCE_LOG!A:A,A35,ATTENDANCE_LOG!B:B,B35),0) -> 0 | E35: =IFERROR(VLOOKUP(B35,COURSE_PLAN!A:B,2,0),0) -> 10 | F35: =IFERROR(MIN(D35/E35,1),0) -> 0 | G35: =IF(E35=0,"—",REPT("█",ROUND(F35*20,0))&REPT("░",20-ROUND(F35*20,0))) -> ░░░░░░░░░░░░░░░░░░░░ | H35: =IF(E35=0,"No plan",IF(F35>=1,"✅ Done",IF(F35>=0.75,"🟢 Almost",IF(F35>=0.25,"🔄 In progress",IF(F35>0,"🟡 Just started","⚪ Not started"))))) -> ⚪ Not started
A36: EL001 | B36: Communication 2 | C36: =IFERROR(VLOOKUP(A36,PIC!A:B,2,0),"") -> Anh Vu | D36: =IFERROR(_xludf.MAXIFS(ATTENDANCE_LOG!E:E,ATTENDANCE_LOG!A:A,A36,ATTENDANCE_LOG!B:B,B36),0) -> 0 | E36: =IFERROR(VLOOKUP(B36,COURSE_PLAN!A:B,2,0),0) -> 16 | F36: =IFERROR(MIN(D36/E36,1),0) -> 0 | G36: =IF(E36=0,"—",REPT("█",ROUND(F36*20,0))&REPT("░",20-ROUND(F36*20,0))) -> ░░░░░░░░░░░░░░░░░░░░ | H36: =IF(E36=0,"No plan",IF(F36>=1,"✅ Done",IF(F36>=0.75,"🟢 Almost",IF(F36>=0.25,"🔄 In progress",IF(F36>0,"🟡 Just started","⚪ Not started"))))) -> ⚪ Not started
A37: EL002 | B37: Communication 1 | C37: =IFERROR(VLOOKUP(A37,PIC!A:B,2,0),"") -> Buu Do 1 | D37: =IFERROR(_xludf.MAXIFS(ATTENDANCE_LOG!E:E,ATTENDANCE_LOG!A:A,A37,ATTENDANCE_LOG!B:B,B37),0) -> 0 | E37: =IFERROR(VLOOKUP(B37,COURSE_PLAN!A:B,2,0),0) -> 10 | F37: =IFERROR(MIN(D37/E37,1),0) -> 0 | G37: =IF(E37=0,"—",REPT("█",ROUND(F37*20,0))&REPT("░",20-ROUND(F37*20,0))) -> ░░░░░░░░░░░░░░░░░░░░ | H37: =IF(E37=0,"No plan",IF(F37>=1,"✅ Done",IF(F37>=0.75,"🟢 Almost",IF(F37>=0.25,"🔄 In progress",IF(F37>0,"🟡 Just started","⚪ Not started"))))) -> ⚪ Not started
A38: EL003 | B38: Communication 1 | C38: =IFERROR(VLOOKUP(A38,PIC!A:B,2,0),"") -> Buu Do 2 | D38: =IFERROR(_xludf.MAXIFS(ATTENDANCE_LOG!E:E,ATTENDANCE_LOG!A:A,A38,ATTENDANCE_LOG!B:B,B38),0) -> 0 | E38: =IFERROR(VLOOKUP(B38,COURSE_PLAN!A:B,2,0),0) -> 10 | F38: =IFERROR(MIN(D38/E38,1),0) -> 0 | G38: =IF(E38=0,"—",REPT("█",ROUND(F38*20,0))&REPT("░",20-ROUND(F38*20,0))) -> ░░░░░░░░░░░░░░░░░░░░ | H38: =IF(E38=0,"No plan",IF(F38>=1,"✅ Done",IF(F38>=0.75,"🟢 Almost",IF(F38>=0.25,"🔄 In progress",IF(F38>0,"🟡 Just started","⚪ Not started"))))) -> ⚪ Not started
A39: EL004 | B39: Communication 1 | C39: =IFERROR(VLOOKUP(A39,PIC!A:B,2,0),"") -> Cuong Nguyen | D39: =IFERROR(_xludf.MAXIFS(ATTENDANCE_LOG!E:E,ATTENDANCE_LOG!A:A,A39,ATTENDANCE_LOG!B:B,B39),0) -> 0 | E39: =IFERROR(VLOOKUP(B39,COURSE_PLAN!A:B,2,0),0) -> 10 | F39: =IFERROR(MIN(D39/E39,1),0) -> 0 | G39: =IF(E39=0,"—",REPT("█",ROUND(F39*20,0))&REPT("░",20-ROUND(F39*20,0))) -> ░░░░░░░░░░░░░░░░░░░░ | H39: =IF(E39=0,"No plan",IF(F39>=1,"✅ Done",IF(F39>=0.75,"🟢 Almost",IF(F39>=0.25,"🔄 In progress",IF(F39>0,"🟡 Just started","⚪ Not started"))))) -> ⚪ Not started
A40: EL004 | B40: Communication 2 | C40: =IFERROR(VLOOKUP(A40,PIC!A:B,2,0),"") -> Cuong Nguyen | D40: =IFERROR(_xludf.MAXIFS(ATTENDANCE_LOG!E:E,ATTENDANCE_LOG!A:A,A40,ATTENDANCE_LOG!B:B,B40),0) -> 0 | E40: =IFERROR(VLOOKUP(B40,COURSE_PLAN!A:B,2,0),0) -> 16 | F40: =IFERROR(MIN(D40/E40,1),0) -> 0 | G40: =IF(E40=0,"—",REPT("█",ROUND(F40*20,0))&REPT("░",20-ROUND(F40*20,0))) -> ░░░░░░░░░░░░░░░░░░░░ | H40: =IF(E40=0,"No plan",IF(F40>=1,"✅ Done",IF(F40>=0.75,"🟢 Almost",IF(F40>=0.25,"🔄 In progress",IF(F40>0,"🟡 Just started","⚪ Not started"))))) -> ⚪ Not started
A41: EL005 | B41: Communication 1 | C41: =IFERROR(VLOOKUP(A41,PIC!A:B,2,0),"") -> Duc Nguyen | D41: =IFERROR(_xludf.MAXIFS(ATTENDANCE_LOG!E:E,ATTENDANCE_LOG!A:A,A41,ATTENDANCE_LOG!B:B,B41),0) -> 0 | E41: =IFERROR(VLOOKUP(B41,COURSE_PLAN!A:B,2,0),0) -> 10 | F41: =IFERROR(MIN(D41/E41,1),0) -> 0 | G41: =IF(E41=0,"—",REPT("█",ROUND(F41*20,0))&REPT("░",20-ROUND(F41*20,0))) -> ░░░░░░░░░░░░░░░░░░░░ | H41: =IF(E41=0,"No plan",IF(F41>=1,"✅ Done",IF(F41>=0.75,"🟢 Almost",IF(F41>=0.25,"🔄 In progress",IF(F41>0,"🟡 Just started","⚪ Not started"))))) -> ⚪ Not started
A42: EL006 | B42: Communication 1 | C42: =IFERROR(VLOOKUP(A42,PIC!A:B,2,0),"") -> Dat Nguyen | D42: =IFERROR(_xludf.MAXIFS(ATTENDANCE_LOG!E:E,ATTENDANCE_LOG!A:A,A42,ATTENDANCE_LOG!B:B,B42),0) -> 0 | E42: =IFERROR(VLOOKUP(B42,COURSE_PLAN!A:B,2,0),0) -> 10 | F42: =IFERROR(MIN(D42/E42,1),0) -> 0 | G42: =IF(E42=0,"—",REPT("█",ROUND(F42*20,0))&REPT("░",20-ROUND(F42*20,0))) -> ░░░░░░░░░░░░░░░░░░░░ | H42: =IF(E42=0,"No plan",IF(F42>=1,"✅ Done",IF(F42>=0.75,"🟢 Almost",IF(F42>=0.25,"🔄 In progress",IF(F42>0,"🟡 Just started","⚪ Not started"))))) -> ⚪ Not started
A43: EL007 | B43: Communication 1 | C43: =IFERROR(VLOOKUP(A43,PIC!A:B,2,0),"") -> Nhat Nguyen | D43: =IFERROR(_xludf.MAXIFS(ATTENDANCE_LOG!E:E,ATTENDANCE_LOG!A:A,A43,ATTENDANCE_LOG!B:B,B43),0) -> 0 | E43: =IFERROR(VLOOKUP(B43,COURSE_PLAN!A:B,2,0),0) -> 10 | F43: =IFERROR(MIN(D43/E43,1),0) -> 0 | G43: =IF(E43=0,"—",REPT("█",ROUND(F43*20,0))&REPT("░",20-ROUND(F43*20,0))) -> ░░░░░░░░░░░░░░░░░░░░ | H43: =IF(E43=0,"No plan",IF(F43>=1,"✅ Done",IF(F43>=0.75,"🟢 Almost",IF(F43>=0.25,"🔄 In progress",IF(F43>0,"🟡 Just started","⚪ Not started"))))) -> ⚪ Not started
A44: EL007 | B44: Communication 2 | C44: =IFERROR(VLOOKUP(A44,PIC!A:B,2,0),"") -> Nhat Nguyen | D44: =IFERROR(_xludf.MAXIFS(ATTENDANCE_LOG!E:E,ATTENDANCE_LOG!A:A,A44,ATTENDANCE_LOG!B:B,B44),0) -> 0 | E44: =IFERROR(VLOOKUP(B44,COURSE_PLAN!A:B,2,0),0) -> 16 | F44: =IFERROR(MIN(D44/E44,1),0) -> 0 | G44: =IF(E44=0,"—",REPT("█",ROUND(F44*20,0))&REPT("░",20-ROUND(F44*20,0))) -> ░░░░░░░░░░░░░░░░░░░░ | H44: =IF(E44=0,"No plan",IF(F44>=1,"✅ Done",IF(F44>=0.75,"🟢 Almost",IF(F44>=0.25,"🔄 In progress",IF(F44>0,"🟡 Just started","⚪ Not started"))))) -> ⚪ Not started
...

Sheet STUDENTS
A1: Input | B1: Input | E1: Formula | F1: Formula | G1: Formula | J1: Formula | K1: Formula | L1: Formula | M1: Input | N1: Input | R1: 247118 | S1: Left | T1: Resgined | U1: =IFERROR(__xludf.DUMMYFUNCTION("arrayformula(vlookup(to_text(R1),to_text($A$4:$B1002),2,0))"),"#N/A") -> #N/A
A2: Emp Code | B2: Full Name | C2: BU | D2: ROLE | E2: Status | F2: PIC | G2: Current Course | H2: Entrance Level | I2: Current Level | J2: Last Active Date | K2: Days Since Active | L2: Drop Flag (<30 days is safe) | M2: Define of drop (not inc. resign) | N2: Drop reason | O2: Remark
A3: 203746 | B3: BẠCH NAM MINH TRÍ | C3: =IFERROR(__xludf.DUMMYFUNCTION("arrayformula(VLOOKUP(to_Text(A3),to_Text(sheet2!$A$1:M1002),13,0))"),"MOC") -> MOC | D3: =IFERROR(__xludf.DUMMYFUNCTION("arrayformula(VLOOKUP(to_Text(A3),to_Text(sheet2!$A$1:M1002),12,0))"),"DEV") -> DEV | E3: Inactive | F3: {=IFERROR( INDEX(ATTENDANCE_INPUT!D:D, MATCH(1, (ATTENDANCE_INPUT!A:A=A3) * (ATTENDANCE_INPUT!V:V=_xludf.MAXIFS(ATTENDANCE_INPUT!V:V, ATTENDANCE_INPUT!A:A, A3)), 0)), "")} | G3: {=IFERROR( INDEX(ATTENDANCE_INPUT!E:E, MATCH(1, (ATTENDANCE_INPUT!A:A=A3) * (ATTENDANCE_INPUT!V:V=_xludf.MAXIFS(ATTENDANCE_INPUT!V:V, ATTENDANCE_INPUT!A:A, A3)), 0)), "")} | H3: {=IF(ISNA(MATCH(A3,sheet2!A:A,0)),"⏳ Chưa test",IFERROR(INDEX(LEVEL_HELPER!A:A,MATCH(INDEX(sheet2!N:N,MATCH(A3,sheet2!A:A,0)),LEVEL_HELPER!B:B,0)),"⏳ Chưa test"))} -> ⏳ Chưa test | I3: {=IF(ISNA(MATCH(A3,sheet2!A:A,0)),H3,IF(INDEX(sheet2!O:O,MATCH(A3,sheet2!A:A,0))>0,IFERROR(INDEX(LEVEL_HELPER!A:A,MATCH(INDEX(sheet2!O:O,MATCH(A3,sheet2!A:A,0)),LEVEL_HELPER!B:B,0)),H3),H3))} -> ⏳ Chưa test | J3: =IFERROR(_xludf.MAXIFS(ATTENDANCE_LOG!F:F, ATTENDANCE_LOG!C:C, A3&"", ATTENDANCE_LOG!G:G, "Present"), "") | K3: =IF(J3="", "", IFERROR(TODAY()-DATEVALUE(LEFT(J3,10)), "")) | L3: =IF(AND(ISNUMBER(K3), K3>=30), "⚠ Possibly Dropped", "") | M3: Completed (no continuation) | N3: High workload
A4: 213817 | B4: Bui Duy Tan | C4: =IFERROR(__xludf.DUMMYFUNCTION("arrayformula(VLOOKUP(to_Text(A4),to_Text(sheet2!$A$1:M1002),13,0))"),"ONC") -> ONC | D4: =IFERROR(__xludf.DUMMYFUNCTION("arrayformula(VLOOKUP(to_Text(A4),to_Text(sheet2!$A$1:M1002),12,0))"),"QC") -> QC | E4: =IF(L4="⚠ Possibly Dropped","Inactive","Active") -> Active | F4: {=IFERROR( INDEX(ATTENDANCE_INPUT!D:D, MATCH(1, (ATTENDANCE_INPUT!A:A=A4) * (ATTENDANCE_INPUT!V:V=_xludf.MAXIFS(ATTENDANCE_INPUT!V:V, ATTENDANCE_INPUT!A:A, A4)), 0)), "")} | G4: {=IFERROR( INDEX(ATTENDANCE_INPUT!E:E, MATCH(1, (ATTENDANCE_INPUT!A:A=A4) * (ATTENDANCE_INPUT!V:V=_xludf.MAXIFS(ATTENDANCE_INPUT!V:V, ATTENDANCE_INPUT!A:A, A4)), 0)), "")} | H4: {=IF(ISNA(MATCH(A4,sheet2!A:A,0)),"⏳ Chưa test",IFERROR(INDEX(LEVEL_HELPER!A:A,MATCH(INDEX(sheet2!N:N,MATCH(A4,sheet2!A:A,0)),LEVEL_HELPER!B:B,0)),"⏳ Chưa test"))} -> Beginner 2 | I4: {=IF(ISNA(MATCH(A4,sheet2!A:A,0)),H4,IF(INDEX(sheet2!O:O,MATCH(A4,sheet2!A:A,0))>0,IFERROR(INDEX(LEVEL_HELPER!A:A,MATCH(INDEX(sheet2!O:O,MATCH(A4,sheet2!A:A,0)),LEVEL_HELPER!B:B,0)),H4),H4))} -> Beginner 2 | J4: =IFERROR(_xludf.MAXIFS(ATTENDANCE_LOG!F:F, ATTENDANCE_LOG!C:C, A4&"", ATTENDANCE_LOG!G:G, "Present"), "") | K4: =IF(J4="", "", IFERROR(TODAY()-DATEVALUE(LEFT(J4,10)), "")) | L4: =IF(AND(ISNUMBER(K4), K4>=30), "⚠ Possibly Dropped", "")
A5: 247037 | B5: BÙI HUỲNH TRUNG TÍN | C5: =IFERROR(__xludf.DUMMYFUNCTION("arrayformula(VLOOKUP(to_Text(A5),to_Text(sheet2!$A$1:M1002),13,0))"),"CHORUS") -> CHORUS | D5: =IFERROR(__xludf.DUMMYFUNCTION("arrayformula(VLOOKUP(to_Text(A5),to_Text(sheet2!$A$1:M1002),12,0))"),"DEV") -> DEV | E5: Inactive | F5: {=IFERROR( INDEX(ATTENDANCE_INPUT!D:D, MATCH(1, (ATTENDANCE_INPUT!A:A=A5) * (ATTENDANCE_INPUT!V:V=_xludf.MAXIFS(ATTENDANCE_INPUT!V:V, ATTENDANCE_INPUT!A:A, A5)), 0)), "")} | G5: {=IFERROR( INDEX(ATTENDANCE_INPUT!E:E, MATCH(1, (ATTENDANCE_INPUT!A:A=A5) * (ATTENDANCE_INPUT!V:V=_xludf.MAXIFS(ATTENDANCE_INPUT!V:V, ATTENDANCE_INPUT!A:A, A5)), 0)), "")} | H5: {=IF(ISNA(MATCH(A5,sheet2!A:A,0)),"⏳ Chưa test",IFERROR(INDEX(LEVEL_HELPER!A:A,MATCH(INDEX(sheet2!N:N,MATCH(A5,sheet2!A:A,0)),LEVEL_HELPER!B:B,0)),"⏳ Chưa test"))} -> Pre-Intermediate | I5: {=IF(ISNA(MATCH(A5,sheet2!A:A,0)),H5,IF(INDEX(sheet2!O:O,MATCH(A5,sheet2!A:A,0))>0,IFERROR(INDEX(LEVEL_HELPER!A:A,MATCH(INDEX(sheet2!O:O,MATCH(A5,sheet2!A:A,0)),LEVEL_HELPER!B:B,0)),H5),H5))} -> Pre-Intermediate | J5: =IFERROR(_xludf.MAXIFS(ATTENDANCE_LOG!F:F, ATTENDANCE_LOG!C:C, A5&"", ATTENDANCE_LOG!G:G, "Present"), "") | K5: =IF(J5="", "", IFERROR(TODAY()-DATEVALUE(LEFT(J5,10)), "")) | L5: =IF(AND(ISNUMBER(K5), K5>=30), "⚠ Possibly Dropped", "") | M5: Discontinued mid-course | N5: High workload
A6: 212007 | B6: BÙI MINH NHẬT | C6: =IFERROR(__xludf.DUMMYFUNCTION("arrayformula(VLOOKUP(to_Text(A6),to_Text(sheet2!$A$1:M1002),13,0))"),"BSG") -> BSG | D6: =IFERROR(__xludf.DUMMYFUNCTION("arrayformula(VLOOKUP(to_Text(A6),to_Text(sheet2!$A$1:M1002),12,0))"),"HR") -> HR | E6: Inactive | F6: {=IFERROR( INDEX(ATTENDANCE_INPUT!D:D, MATCH(1, (ATTENDANCE_INPUT!A:A=A6) * (ATTENDANCE_INPUT!V:V=_xludf.MAXIFS(ATTENDANCE_INPUT!V:V, ATTENDANCE_INPUT!A:A, A6)), 0)), "")} | G6: {=IFERROR( INDEX(ATTENDANCE_INPUT!E:E, MATCH(1, (ATTENDANCE_INPUT!A:A=A6) * (ATTENDANCE_INPUT!V:V=_xludf.MAXIFS(ATTENDANCE_INPUT!V:V, ATTENDANCE_INPUT!A:A, A6)), 0)), "")} | H6: {=IF(ISNA(MATCH(A6,sheet2!A:A,0)),"⏳ Chưa test",IFERROR(INDEX(LEVEL_HELPER!A:A,MATCH(INDEX(sheet2!N:N,MATCH(A6,sheet2!A:A,0)),LEVEL_HELPER!B:B,0)),"⏳ Chưa test"))} -> Pre-Intermediate | I6: {=IF(ISNA(MATCH(A6,sheet2!A:A,0)),H6,IF(INDEX(sheet2!O:O,MATCH(A6,sheet2!A:A,0))>0,IFERROR(INDEX(LEVEL_HELPER!A:A,MATCH(INDEX(sheet2!O:O,MATCH(A6,sheet2!A:A,0)),LEVEL_HELPER!B:B,0)),H6),H6))} -> Pre-Intermediate | J6: =IFERROR(_xludf.MAXIFS(ATTENDANCE_LOG!F:F, ATTENDANCE_LOG!C:C, A6&"", ATTENDANCE_LOG!G:G, "Present"), "") | K6: =IF(J6="", "", IFERROR(TODAY()-DATEVALUE(LEFT(J6,10)), "")) | L6: =IF(AND(ISNUMBER(K6), K6>=30), "⚠ Possibly Dropped", "") | M6: Completed (no continuation) | N6: Prefer different learning format
A7: 193479 | B7: BÙI NGỌC QUỐC | C7: =IFERROR(__xludf.DUMMYFUNCTION("arrayformula(VLOOKUP(to_Text(A7),to_Text(sheet2!$A$1:M1002),13,0))"),"ONC") -> ONC | D7: =IFERROR(__xludf.DUMMYFUNCTION("arrayformula(VLOOKUP(to_Text(A7),to_Text(sheet2!$A$1:M1002),12,0))"),"DEV") -> DEV | E7: =IF(L7="⚠ Possibly Dropped","Inactive","Active") -> Active | F7: {=IFERROR( INDEX(ATTENDANCE_INPUT!D:D, MATCH(1, (ATTENDANCE_INPUT!A:A=A7) * (ATTENDANCE_INPUT!V:V=_xludf.MAXIFS(ATTENDANCE_INPUT!V:V, ATTENDANCE_INPUT!A:A, A7)), 0)), "")} | G7: {=IFERROR( INDEX(ATTENDANCE_INPUT!E:E, MATCH(1, (ATTENDANCE_INPUT!A:A=A7) * (ATTENDANCE_INPUT!V:V=_xludf.MAXIFS(ATTENDANCE_INPUT!V:V, ATTENDANCE_INPUT!A:A, A7)), 0)), "")} | H7: {=IF(ISNA(MATCH(A7,sheet2!A:A,0)),"⏳ Chưa test",IFERROR(INDEX(LEVEL_HELPER!A:A,MATCH(INDEX(sheet2!N:N,MATCH(A7,sheet2!A:A,0)),LEVEL_HELPER!B:B,0)),"⏳ Chưa test"))} -> Beginner | I7: {=IF(ISNA(MATCH(A7,sheet2!A:A,0)),H7,IF(INDEX(sheet2!O:O,MATCH(A7,sheet2!A:A,0))>0,IFERROR(INDEX(LEVEL_HELPER!A:A,MATCH(INDEX(sheet2!O:O,MATCH(A7,sheet2!A:A,0)),LEVEL_HELPER!B:B,0)),H7),H7))} -> Beginner | J7: =IFERROR(_xludf.MAXIFS(ATTENDANCE_LOG!F:F, ATTENDANCE_LOG!C:C, A7&"", ATTENDANCE_LOG!G:G, "Present"), "") | K7: =IF(J7="", "", IFERROR(TODAY()-DATEVALUE(LEFT(J7,10)), "")) | L7: =IF(AND(ISNUMBER(K7), K7>=30), "⚠ Possibly Dropped", "") | M7: Completed (no continuation) | N7: Learning goal achieved | R7: 247329 | S7: High workload / Can't arrange time | T7: High workload | U7: #N/A
A8: 237226 | B8: CHU KHÁNH LINH | C8: =IFERROR(__xludf.DUMMYFUNCTION("arrayformula(VLOOKUP(to_Text(A8),to_Text(sheet2!$A$1:M1002),13,0))"),"LBU") -> LBU | D8: =IFERROR(__xludf.DUMMYFUNCTION("arrayformula(VLOOKUP(to_Text(A8),to_Text(sheet2!$A$1:M1002),12,0))"),"GSD") -> GSD | E8: =IF(L8="⚠ Possibly Dropped","Inactive","Active") -> Active | F8: {=IFERROR( INDEX(ATTENDANCE_INPUT!D:D, MATCH(1, (ATTENDANCE_INPUT!A:A=A8) * (ATTENDANCE_INPUT!V:V=_xludf.MAXIFS(ATTENDANCE_INPUT!V:V, ATTENDANCE_INPUT!A:A, A8)), 0)), "")} | G8: {=IFERROR( INDEX(ATTENDANCE_INPUT!E:E, MATCH(1, (ATTENDANCE_INPUT!A:A=A8) * (ATTENDANCE_INPUT!V:V=_xludf.MAXIFS(ATTENDANCE_INPUT!V:V, ATTENDANCE_INPUT!A:A, A8)), 0)), "")} | H8: {=IF(ISNA(MATCH(A8,sheet2!A:A,0)),"⏳ Chưa test",IFERROR(INDEX(LEVEL_HELPER!A:A,MATCH(INDEX(sheet2!N:N,MATCH(A8,sheet2!A:A,0)),LEVEL_HELPER!B:B,0)),"⏳ Chưa test"))} -> Beginner | I8: {=IF(ISNA(MATCH(A8,sheet2!A:A,0)),H8,IF(INDEX(sheet2!O:O,MATCH(A8,sheet2!A:A,0))>0,IFERROR(INDEX(LEVEL_HELPER!A:A,MATCH(INDEX(sheet2!O:O,MATCH(A8,sheet2!A:A,0)),LEVEL_HELPER!B:B,0)),H8),H8))} -> Beginner | J8: =IFERROR(_xludf.MAXIFS(ATTENDANCE_LOG!F:F, ATTENDANCE_LOG!C:C, A8&"", ATTENDANCE_LOG!G:G, "Present"), "") | K8: =IF(J8="", "", IFERROR(TODAY()-DATEVALUE(LEFT(J8,10)), "")) | L8: =IF(AND(ISNUMBER(K8), K8>=30), "⚠ Possibly Dropped", "")
A9: 213856 | B9: Chu Thị Lệ Quỳnh | C9: =IFERROR(__xludf.DUMMYFUNCTION("arrayformula(VLOOKUP(to_Text(A9),to_Text(sheet2!$A$1:M1002),13,0))"),"ONC") -> ONC | D9: =IFERROR(__xludf.DUMMYFUNCTION("arrayformula(VLOOKUP(to_Text(A9),to_Text(sheet2!$A$1:M1002),12,0))"),"QC") -> QC | E9: =IF(L9="⚠ Possibly Dropped","Inactive","Active") -> Active | F9: {=IFERROR( INDEX(ATTENDANCE_INPUT!D:D, MATCH(1, (ATTENDANCE_INPUT!A:A=A9) * (ATTENDANCE_INPUT!V:V=_xludf.MAXIFS(ATTENDANCE_INPUT!V:V, ATTENDANCE_INPUT!A:A, A9)), 0)), "")} | G9: {=IFERROR( INDEX(ATTENDANCE_INPUT!E:E, MATCH(1, (ATTENDANCE_INPUT!A:A=A9) * (ATTENDANCE_INPUT!V:V=_xludf.MAXIFS(ATTENDANCE_INPUT!V:V, ATTENDANCE_INPUT!A:A, A9)), 0)), "")} | H9: {=IF(ISNA(MATCH(A9,sheet2!A:A,0)),"⏳ Chưa test",IFERROR(INDEX(LEVEL_HELPER!A:A,MATCH(INDEX(sheet2!N:N,MATCH(A9,sheet2!A:A,0)),LEVEL_HELPER!B:B,0)),"⏳ Chưa test"))} -> Beginner | I9: {=IF(ISNA(MATCH(A9,sheet2!A:A,0)),H9,IF(INDEX(sheet2!O:O,MATCH(A9,sheet2!A:A,0))>0,IFERROR(INDEX(LEVEL_HELPER!A:A,MATCH(INDEX(sheet2!O:O,MATCH(A9,sheet2!A:A,0)),LEVEL_HELPER!B:B,0)),H9),H9))} -> Beginner | J9: =IFERROR(_xludf.MAXIFS(ATTENDANCE_LOG!F:F, ATTENDANCE_LOG!C:C, A9&"", ATTENDANCE_LOG!G:G, "Present"), "") | K9: =IF(J9="", "", IFERROR(TODAY()-DATEVALUE(LEFT(J9,10)), "")) | L9: =IF(AND(ISNUMBER(K9), K9>=30), "⚠ Possibly Dropped", "")
A10: 247423 | B10: CHUNG QUANG PHƯƠNG | C10: =IFERROR(__xludf.DUMMYFUNCTION("arrayformula(VLOOKUP(to_Text(A10),to_Text(sheet2!$A$1:M1002),13,0))"),"MOC") -> MOC | D10: =IFERROR(__xludf.DUMMYFUNCTION("arrayformula(VLOOKUP(to_Text(A10),to_Text(sheet2!$A$1:M1002),12,0))"),"DEV") -> DEV | E10: =IF(L10="⚠ Possibly Dropped","Inactive","Active") -> Active | F10: {=IFERROR( INDEX(ATTENDANCE_INPUT!D:D, MATCH(1, (ATTENDANCE_INPUT!A:A=A10) * (ATTENDANCE_INPUT!V:V=_xludf.MAXIFS(ATTENDANCE_INPUT!V:V, ATTENDANCE_INPUT!A:A, A10)), 0)), "")} | G10: {=IFERROR( INDEX(ATTENDANCE_INPUT!E:E, MATCH(1, (ATTENDANCE_INPUT!A:A=A10) * (ATTENDANCE_INPUT!V:V=_xludf.MAXIFS(ATTENDANCE_INPUT!V:V, ATTENDANCE_INPUT!A:A, A10)), 0)), "")} | H10: {=IF(ISNA(MATCH(A10,sheet2!A:A,0)),"⏳ Chưa test",IFERROR(INDEX(LEVEL_HELPER!A:A,MATCH(INDEX(sheet2!N:N,MATCH(A10,sheet2!A:A,0)),LEVEL_HELPER!B:B,0)),"⏳ Chưa test"))} -> Foundation | I10: {=IF(ISNA(MATCH(A10,sheet2!A:A,0)),H10,IF(INDEX(sheet2!O:O,MATCH(A10,sheet2!A:A,0))>0,IFERROR(INDEX(LEVEL_HELPER!A:A,MATCH(INDEX(sheet2!O:O,MATCH(A10,sheet2!A:A,0)),LEVEL_HELPER!B:B,0)),H10),H10))} -> Foundation | J10: =IFERROR(_xludf.MAXIFS(ATTENDANCE_LOG!F:F, ATTENDANCE_LOG!C:C, A10&"", ATTENDANCE_LOG!G:G, "Present"), "") | K10: =IF(J10="", "", IFERROR(TODAY()-DATEVALUE(LEFT(J10,10)), "")) | L10: =IF(AND(ISNUMBER(K10), K10>=30), "⚠ Possibly Dropped", "")
A11: 213881 | B11: ĐẶNG GIA LỘC | C11: =IFERROR(__xludf.DUMMYFUNCTION("arrayformula(VLOOKUP(to_Text(A11),to_Text(sheet2!$A$1:M1002),13,0))"),"MOC") -> MOC | D11: =IFERROR(__xludf.DUMMYFUNCTION("arrayformula(VLOOKUP(to_Text(A11),to_Text(sheet2!$A$1:M1002),12,0))"),"DEV") -> DEV | E11: =IF(L11="⚠ Possibly Dropped","Inactive","Active") -> Active | F11: {=IFERROR( INDEX(ATTENDANCE_INPUT!D:D, MATCH(1, (ATTENDANCE_INPUT!A:A=A11) * (ATTENDANCE_INPUT!V:V=_xludf.MAXIFS(ATTENDANCE_INPUT!V:V, ATTENDANCE_INPUT!A:A, A11)), 0)), "")} | G11: {=IFERROR( INDEX(ATTENDANCE_INPUT!E:E, MATCH(1, (ATTENDANCE_INPUT!A:A=A11) * (ATTENDANCE_INPUT!V:V=_xludf.MAXIFS(ATTENDANCE_INPUT!V:V, ATTENDANCE_INPUT!A:A, A11)), 0)), "")} | H11: {=IF(ISNA(MATCH(A11,sheet2!A:A,0)),"⏳ Chưa test",IFERROR(INDEX(LEVEL_HELPER!A:A,MATCH(INDEX(sheet2!N:N,MATCH(A11,sheet2!A:A,0)),LEVEL_HELPER!B:B,0)),"⏳ Chưa test"))} -> Foundation | I11: {=IF(ISNA(MATCH(A11,sheet2!A:A,0)),H11,IF(INDEX(sheet2!O:O,MATCH(A11,sheet2!A:A,0))>0,IFERROR(INDEX(LEVEL_HELPER!A:A,MATCH(INDEX(sheet2!O:O,MATCH(A11,sheet2!A:A,0)),LEVEL_HELPER!B:B,0)),H11),H11))} -> Foundation | J11: =IFERROR(_xludf.MAXIFS(ATTENDANCE_LOG!F:F, ATTENDANCE_LOG!C:C, A11&"", ATTENDANCE_LOG!G:G, "Present"), "") | K11: =IF(J11="", "", IFERROR(TODAY()-DATEVALUE(LEFT(J11,10)), "")) | L11: =IF(AND(ISNUMBER(K11), K11>=30), "⚠ Possibly Dropped", "") | M11: Completed (no continuation) | N11: Learning goal achieved
A12: 213811 | B12: ĐẶNG QUỐC MẠNH | C12: =IFERROR(__xludf.DUMMYFUNCTION("arrayformula(VLOOKUP(to_Text(A12),to_Text(sheet2!$A$1:M1002),13,0))"),"ONC") -> ONC | D12: =IFERROR(__xludf.DUMMYFUNCTION("arrayformula(VLOOKUP(to_Text(A12),to_Text(sheet2!$A$1:M1002),12,0))"),"DEV") -> DEV | E12: =IF(L12="⚠ Possibly Dropped","Inactive","Active") -> Active | F12: {=IFERROR( INDEX(ATTENDANCE_INPUT!D:D, MATCH(1, (ATTENDANCE_INPUT!A:A=A12) * (ATTENDANCE_INPUT!V:V=_xludf.MAXIFS(ATTENDANCE_INPUT!V:V, ATTENDANCE_INPUT!A:A, A12)), 0)), "")} | G12: {=IFERROR( INDEX(ATTENDANCE_INPUT!E:E, MATCH(1, (ATTENDANCE_INPUT!A:A=A12) * (ATTENDANCE_INPUT!V:V=_xludf.MAXIFS(ATTENDANCE_INPUT!V:V, ATTENDANCE_INPUT!A:A, A12)), 0)), "")} | H12: {=IF(ISNA(MATCH(A12,sheet2!A:A,0)),"⏳ Chưa test",IFERROR(INDEX(LEVEL_HELPER!A:A,MATCH(INDEX(sheet2!N:N,MATCH(A12,sheet2!A:A,0)),LEVEL_HELPER!B:B,0)),"⏳ Chưa test"))} -> Beginner | I12: {=IF(ISNA(MATCH(A12,sheet2!A:A,0)),H12,IF(INDEX(sheet2!O:O,MATCH(A12,sheet2!A:A,0))>0,IFERROR(INDEX(LEVEL_HELPER!A:A,MATCH(INDEX(sheet2!O:O,MATCH(A12,sheet2!A:A,0)),LEVEL_HELPER!B:B,0)),H12),H12))} -> Beginner | J12: =IFERROR(_xludf.MAXIFS(ATTENDANCE_LOG!F:F, ATTENDANCE_LOG!C:C, A12&"", ATTENDANCE_LOG!G:G, "Present"), "") | K12: =IF(J12="", "", IFERROR(TODAY()-DATEVALUE(LEFT(J12,10)), "")) | L12: =IF(AND(ISNUMBER(K12), K12>=30), "⚠ Possibly Dropped", "") | M12: Completed (no continuation) | N12: Learning goal achieved | R12: 247391 | S12: High workload / Can't arrange time | T12: High workload | U12: #N/A
A13: 227125 | B13: ĐẶNG QUỐC VIỆT | C13: =IFERROR(__xludf.DUMMYFUNCTION("arrayformula(VLOOKUP(to_Text(A13),to_Text(sheet2!$A$1:M1002),13,0))"),"CHORUS") -> CHORUS | D13: =IFERROR(__xludf.DUMMYFUNCTION("arrayformula(VLOOKUP(to_Text(A13),to_Text(sheet2!$A$1:M1002),12,0))"),"QC") -> QC | E13: =IF(L13="⚠ Possibly Dropped","Inactive","Active") -> Active | F13: {=IFERROR( INDEX(ATTENDANCE_INPUT!D:D, MATCH(1, (ATTENDANCE_INPUT!A:A=A13) * (ATTENDANCE_INPUT!V:V=_xludf.MAXIFS(ATTENDANCE_INPUT!V:V, ATTENDANCE_INPUT!A:A, A13)), 0)), "")} | G13: {=IFERROR( INDEX(ATTENDANCE_INPUT!E:E, MATCH(1, (ATTENDANCE_INPUT!A:A=A13) * (ATTENDANCE_INPUT!V:V=_xludf.MAXIFS(ATTENDANCE_INPUT!V:V, ATTENDANCE_INPUT!A:A, A13)), 0)), "")} | H13: {=IF(ISNA(MATCH(A13,sheet2!A:A,0)),"⏳ Chưa test",IFERROR(INDEX(LEVEL_HELPER!A:A,MATCH(INDEX(sheet2!N:N,MATCH(A13,sheet2!A:A,0)),LEVEL_HELPER!B:B,0)),"⏳ Chưa test"))} -> Beginner | I13: {=IF(ISNA(MATCH(A13,sheet2!A:A,0)),H13,IF(INDEX(sheet2!O:O,MATCH(A13,sheet2!A:A,0))>0,IFERROR(INDEX(LEVEL_HELPER!A:A,MATCH(INDEX(sheet2!O:O,MATCH(A13,sheet2!A:A,0)),LEVEL_HELPER!B:B,0)),H13),H13))} -> Beginner | J13: =IFERROR(_xludf.MAXIFS(ATTENDANCE_LOG!F:F, ATTENDANCE_LOG!C:C, A13&"", ATTENDANCE_LOG!G:G, "Present"), "") | K13: =IF(J13="", "", IFERROR(TODAY()-DATEVALUE(LEFT(J13,10)), "")) | L13: =IF(AND(ISNUMBER(K13), K13>=30), "⚠ Possibly Dropped", "") | M13: Discontinued mid-course | N13: Team restructuring
A14: 173272 | B14: ĐÀO SỸ THỜI | C14: =IFERROR(__xludf.DUMMYFUNCTION("arrayformula(VLOOKUP(to_Text(A14),to_Text(sheet2!$A$1:M1002),13,0))"),"LBU") -> LBU | D14: =IFERROR(__xludf.DUMMYFUNCTION("arrayformula(VLOOKUP(to_Text(A14),to_Text(sheet2!$A$1:M1002),12,0))"),"GSD") -> GSD | E14: =IF(L14="⚠ Possibly Dropped","Inactive","Active") -> Active | F14: {=IFERROR( INDEX(ATTENDANCE_INPUT!D:D, MATCH(1, (ATTENDANCE_INPUT!A:A=A14) * (ATTENDANCE_INPUT!V:V=_xludf.MAXIFS(ATTENDANCE_INPUT!V:V, ATTENDANCE_INPUT!A:A, A14)), 0)), "")} | G14: {=IFERROR( INDEX(ATTENDANCE_INPUT!E:E, MATCH(1, (ATTENDANCE_INPUT!A:A=A14) * (ATTENDANCE_INPUT!V:V=_xludf.MAXIFS(ATTENDANCE_INPUT!V:V, ATTENDANCE_INPUT!A:A, A14)), 0)), "")} | H14: {=IF(ISNA(MATCH(A14,sheet2!A:A,0)),"⏳ Chưa test",IFERROR(INDEX(LEVEL_HELPER!A:A,MATCH(INDEX(sheet2!N:N,MATCH(A14,sheet2!A:A,0)),LEVEL_HELPER!B:B,0)),"⏳ Chưa test"))} -> Beginner | I14: {=IF(ISNA(MATCH(A14,sheet2!A:A,0)),H14,IF(INDEX(sheet2!O:O,MATCH(A14,sheet2!A:A,0))>0,IFERROR(INDEX(LEVEL_HELPER!A:A,MATCH(INDEX(sheet2!O:O,MATCH(A14,sheet2!A:A,0)),LEVEL_HELPER!B:B,0)),H14),H14))} -> Beginner | J14: =IFERROR(_xludf.MAXIFS(ATTENDANCE_LOG!F:F, ATTENDANCE_LOG!C:C, A14&"", ATTENDANCE_LOG!G:G, "Present"), "") | K14: =IF(J14="", "", IFERROR(TODAY()-DATEVALUE(LEFT(J14,10)), "")) | L14: =IF(AND(ISNUMBER(K14), K14>=30), "⚠ Possibly Dropped", "")
A15: 183322 | B15: ĐÀO TRUNG HIẾU | C15: =IFERROR(__xludf.DUMMYFUNCTION("arrayformula(VLOOKUP(to_Text(A15),to_Text(sheet2!$A$1:M1002),13,0))"),"MOC") -> MOC | D15: =IFERROR(__xludf.DUMMYFUNCTION("arrayformula(VLOOKUP(to_Text(A15),to_Text(sheet2!$A$1:M1002),12,0))"),"DEV") -> DEV | E15: =IF(L15="⚠ Possibly Dropped","Inactive","Active") -> Active | F15: {=IFERROR( INDEX(ATTENDANCE_INPUT!D:D, MATCH(1, (ATTENDANCE_INPUT!A:A=A15) * (ATTENDANCE_INPUT!V:V=_xludf.MAXIFS(ATTENDANCE_INPUT!V:V, ATTENDANCE_INPUT!A:A, A15)), 0)), "")} | G15: {=IFERROR( INDEX(ATTENDANCE_INPUT!E:E, MATCH(1, (ATTENDANCE_INPUT!A:A=A15) * (ATTENDANCE_INPUT!V:V=_xludf.MAXIFS(ATTENDANCE_INPUT!V:V, ATTENDANCE_INPUT!A:A, A15)), 0)), "")} | H15: {=IF(ISNA(MATCH(A15,sheet2!A:A,0)),"⏳ Chưa test",IFERROR(INDEX(LEVEL_HELPER!A:A,MATCH(INDEX(sheet2!N:N,MATCH(A15,sheet2!A:A,0)),LEVEL_HELPER!B:B,0)),"⏳ Chưa test"))} -> Foundation | I15: {=IF(ISNA(MATCH(A15,sheet2!A:A,0)),H15,IF(INDEX(sheet2!O:O,MATCH(A15,sheet2!A:A,0))>0,IFERROR(INDEX(LEVEL_HELPER!A:A,MATCH(INDEX(sheet2!O:O,MATCH(A15,sheet2!A:A,0)),LEVEL_HELPER!B:B,0)),H15),H15))} -> Foundation | J15: =IFERROR(_xludf.MAXIFS(ATTENDANCE_LOG!F:F, ATTENDANCE_LOG!C:C, A15&"", ATTENDANCE_LOG!G:G, "Present"), "") | K15: =IF(J15="", "", IFERROR(TODAY()-DATEVALUE(LEFT(J15,10)), "")) | L15: =IF(AND(ISNUMBER(K15), K15>=30), "⚠ Possibly Dropped", "")
A16: 257134 | B16: ĐINH QUỐC HUẤN | C16: =IFERROR(__xludf.DUMMYFUNCTION("arrayformula(VLOOKUP(to_Text(A16),to_Text(sheet2!$A$1:M1002),13,0))"),"LBU") -> LBU | D16: =IFERROR(__xludf.DUMMYFUNCTION("arrayformula(VLOOKUP(to_Text(A16),to_Text(sheet2!$A$1:M1002),12,0))"),"Designer") -> Designer | E16: =IF(L16="⚠ Possibly Dropped","Inactive","Active") -> Active | F16: {=IFERROR( INDEX(ATTENDANCE_INPUT!D:D, MATCH(1, (ATTENDANCE_INPUT!A:A=A16) * (ATTENDANCE_INPUT!V:V=_xludf.MAXIFS(ATTENDANCE_INPUT!V:V, ATTENDANCE_INPUT!A:A, A16)), 0)), "")} | G16: {=IFERROR( INDEX(ATTENDANCE_INPUT!E:E, MATCH(1, (ATTENDANCE_INPUT!A:A=A16) * (ATTENDANCE_INPUT!V:V=_xludf.MAXIFS(ATTENDANCE_INPUT!V:V, ATTENDANCE_INPUT!A:A, A16)), 0)), "")} | H16: {=IF(ISNA(MATCH(A16,sheet2!A:A,0)),"⏳ Chưa test",IFERROR(INDEX(LEVEL_HELPER!A:A,MATCH(INDEX(sheet2!N:N,MATCH(A16,sheet2!A:A,0)),LEVEL_HELPER!B:B,0)),"⏳ Chưa test"))} -> Foundation | I16: {=IF(ISNA(MATCH(A16,sheet2!A:A,0)),H16,IF(INDEX(sheet2!O:O,MATCH(A16,sheet2!A:A,0))>0,IFERROR(INDEX(LEVEL_HELPER!A:A,MATCH(INDEX(sheet2!O:O,MATCH(A16,sheet2!A:A,0)),LEVEL_HELPER!B:B,0)),H16),H16))} -> Foundation | J16: =IFERROR(_xludf.MAXIFS(ATTENDANCE_LOG!F:F, ATTENDANCE_LOG!C:C, A16&"", ATTENDANCE_LOG!G:G, "Present"), "") | K16: =IF(J16="", "", IFERROR(TODAY()-DATEVALUE(LEFT(J16,10)), "")) | L16: =IF(AND(ISNUMBER(K16), K16>=30), "⚠ Possibly Dropped", "")
A17: 213863 | B17: ĐINH TIẾN ĐẠT | C17: =IFERROR(__xludf.DUMMYFUNCTION("arrayformula(VLOOKUP(to_Text(A17),to_Text(sheet2!$A$1:M1002),13,0))"),"MOC") -> MOC | D17: =IFERROR(__xludf.DUMMYFUNCTION("arrayformula(VLOOKUP(to_Text(A17),to_Text(sheet2!$A$1:M1002),12,0))"),"DEV") -> DEV | E17: =IF(L17="⚠ Possibly Dropped","Inactive","Active") -> Active | F17: {=IFERROR( INDEX(ATTENDANCE_INPUT!D:D, MATCH(1, (ATTENDANCE_INPUT!A:A=A17) * (ATTENDANCE_INPUT!V:V=_xludf.MAXIFS(ATTENDANCE_INPUT!V:V, ATTENDANCE_INPUT!A:A, A17)), 0)), "")} | G17: {=IFERROR( INDEX(ATTENDANCE_INPUT!E:E, MATCH(1, (ATTENDANCE_INPUT!A:A=A17) * (ATTENDANCE_INPUT!V:V=_xludf.MAXIFS(ATTENDANCE_INPUT!V:V, ATTENDANCE_INPUT!A:A, A17)), 0)), "")} | H17: {=IF(ISNA(MATCH(A17,sheet2!A:A,0)),"⏳ Chưa test",IFERROR(INDEX(LEVEL_HELPER!A:A,MATCH(INDEX(sheet2!N:N,MATCH(A17,sheet2!A:A,0)),LEVEL_HELPER!B:B,0)),"⏳ Chưa test"))} -> Beginner | I17: {=IF(ISNA(MATCH(A17,sheet2!A:A,0)),H17,IF(INDEX(sheet2!O:O,MATCH(A17,sheet2!A:A,0))>0,IFERROR(INDEX(LEVEL_HELPER!A:A,MATCH(INDEX(sheet2!O:O,MATCH(A17,sheet2!A:A,0)),LEVEL_HELPER!B:B,0)),H17),H17))} -> Beginner | J17: =IFERROR(_xludf.MAXIFS(ATTENDANCE_LOG!F:F, ATTENDANCE_LOG!C:C, A17&"", ATTENDANCE_LOG!G:G, "Present"), "") | K17: =IF(J17="", "", IFERROR(TODAY()-DATEVALUE(LEFT(J17,10)), "")) | L17: =IF(AND(ISNUMBER(K17), K17>=30), "⚠ Possibly Dropped", "") | M17: Discontinued mid-course | N17: High workload
A18: 247389 | B18: ĐINH TRƯƠNG THANH TUYỀN | C18: =IFERROR(__xludf.DUMMYFUNCTION("arrayformula(VLOOKUP(to_Text(A18),to_Text(sheet2!$A$1:M1002),13,0))"),"LBU") -> LBU | D18: =IFERROR(__xludf.DUMMYFUNCTION("arrayformula(VLOOKUP(to_Text(A18),to_Text(sheet2!$A$1:M1002),12,0))"),"QC") -> QC | E18: =IF(L18="⚠ Possibly Dropped","Inactive","Active") -> Active | F18: {=IFERROR( INDEX(ATTENDANCE_INPUT!D:D, MATCH(1, (ATTENDANCE_INPUT!A:A=A18) * (ATTENDANCE_INPUT!V:V=_xludf.MAXIFS(ATTENDANCE_INPUT!V:V, ATTENDANCE_INPUT!A:A, A18)), 0)), "")} | G18: {=IFERROR( INDEX(ATTENDANCE_INPUT!E:E, MATCH(1, (ATTENDANCE_INPUT!A:A=A18) * (ATTENDANCE_INPUT!V:V=_xludf.MAXIFS(ATTENDANCE_INPUT!V:V, ATTENDANCE_INPUT!A:A, A18)), 0)), "")} | H18: {=IF(ISNA(MATCH(A18,sheet2!A:A,0)),"⏳ Chưa test",IFERROR(INDEX(LEVEL_HELPER!A:A,MATCH(INDEX(sheet2!N:N,MATCH(A18,sheet2!A:A,0)),LEVEL_HELPER!B:B,0)),"⏳ Chưa test"))} -> ⏳ Chưa test | I18: {=IF(ISNA(MATCH(A18,sheet2!A:A,0)),H18,IF(INDEX(sheet2!O:O,MATCH(A18,sheet2!A:A,0))>0,IFERROR(INDEX(LEVEL_HELPER!A:A,MATCH(INDEX(sheet2!O:O,MATCH(A18,sheet2!A:A,0)),LEVEL_HELPER!B:B,0)),H18),H18))} -> ⏳ Chưa test | J18: =IFERROR(_xludf.MAXIFS(ATTENDANCE_LOG!F:F, ATTENDANCE_LOG!C:C, A18&"", ATTENDANCE_LOG!G:G, "Present"), "") | K18: =IF(J18="", "", IFERROR(TODAY()-DATEVALUE(LEFT(J18,10)), "")) | L18: =IF(AND(ISNUMBER(K18), K18>=30), "⚠ Possibly Dropped", "") | M18: Discontinued mid-course | N18: Prefer different learning format | O18: 4/2026: Chờ khóa Com3
A19: 247300 | B19: ĐỖ CHÂU BỬU | C19: =IFERROR(__xludf.DUMMYFUNCTION("arrayformula(VLOOKUP(to_Text(A19),to_Text(sheet2!$A$1:M1002),13,0))"),"CHORUS") -> CHORUS | D19: =IFERROR(__xludf.DUMMYFUNCTION("arrayformula(VLOOKUP(to_Text(A19),to_Text(sheet2!$A$1:M1002),12,0))"),"SM") -> SM | E19: Inactive | F19: {=IFERROR( INDEX(ATTENDANCE_INPUT!D:D, MATCH(1, (ATTENDANCE_INPUT!A:A=A19) * (ATTENDANCE_INPUT!V:V=_xludf.MAXIFS(ATTENDANCE_INPUT!V:V, ATTENDANCE_INPUT!A:A, A19)), 0)), "")} | G19: {=IFERROR( INDEX(ATTENDANCE_INPUT!E:E, MATCH(1, (ATTENDANCE_INPUT!A:A=A19) * (ATTENDANCE_INPUT!V:V=_xludf.MAXIFS(ATTENDANCE_INPUT!V:V, ATTENDANCE_INPUT!A:A, A19)), 0)), "")} | H19: {=IF(ISNA(MATCH(A19,sheet2!A:A,0)),"⏳ Chưa test",IFERROR(INDEX(LEVEL_HELPER!A:A,MATCH(INDEX(sheet2!N:N,MATCH(A19,sheet2!A:A,0)),LEVEL_HELPER!B:B,0)),"⏳ Chưa test"))} -> Pre-Intermediate | I19: {=IF(ISNA(MATCH(A19,sheet2!A:A,0)),H19,IF(INDEX(sheet2!O:O,MATCH(A19,sheet2!A:A,0))>0,IFERROR(INDEX(LEVEL_HELPER!A:A,MATCH(INDEX(sheet2!O:O,MATCH(A19,sheet2!A:A,0)),LEVEL_HELPER!B:B,0)),H19),H19))} -> Pre-Intermediate | J19: =IFERROR(_xludf.MAXIFS(ATTENDANCE_LOG!F:F, ATTENDANCE_LOG!C:C, A19&"", ATTENDANCE_LOG!G:G, "Present"), "") | K19: =IF(J19="", "", IFERROR(TODAY()-DATEVALUE(LEFT(J19,10)), "")) | L19: =IF(AND(ISNUMBER(K19), K19>=30), "⚠ Possibly Dropped", "") | M19: Discontinued mid-course | N19: High workload | R19: 247115 | S19: Ungroup team | T19: Team restructuring | U19: #N/A
A20: 203765 | B20: ĐỖ GIA KHÁNH | C20: =IFERROR(__xludf.DUMMYFUNCTION("arrayformula(VLOOKUP(to_Text(A20),to_Text(sheet2!$A$1:M1002),13,0))"),"MOC") -> MOC | D20: =IFERROR(__xludf.DUMMYFUNCTION("arrayformula(VLOOKUP(to_Text(A20),to_Text(sheet2!$A$1:M1002),12,0))"),"DEV") -> DEV | E20: Waiting for class | F20: {=IFERROR( INDEX(ATTENDANCE_INPUT!D:D, MATCH(1, (ATTENDANCE_INPUT!A:A=A20) * (ATTENDANCE_INPUT!V:V=_xludf.MAXIFS(ATTENDANCE_INPUT!V:V, ATTENDANCE_INPUT!A:A, A20)), 0)), "")} | G20: {=IFERROR( INDEX(ATTENDANCE_INPUT!E:E, MATCH(1, (ATTENDANCE_INPUT!A:A=A20) * (ATTENDANCE_INPUT!V:V=_xludf.MAXIFS(ATTENDANCE_INPUT!V:V, ATTENDANCE_INPUT!A:A, A20)), 0)), "")} | H20: {=IF(ISNA(MATCH(A20,sheet2!A:A,0)),"⏳ Chưa test",IFERROR(INDEX(LEVEL_HELPER!A:A,MATCH(INDEX(sheet2!N:N,MATCH(A20,sheet2!A:A,0)),LEVEL_HELPER!B:B,0)),"⏳ Chưa test"))} -> Beginner | I20: {=IF(ISNA(MATCH(A20,sheet2!A:A,0)),H20,IF(INDEX(sheet2!O:O,MATCH(A20,sheet2!A:A,0))>0,IFERROR(INDEX(LEVEL_HELPER!A:A,MATCH(INDEX(sheet2!O:O,MATCH(A20,sheet2!A:A,0)),LEVEL_HELPER!B:B,0)),H20),H20))} -> Beginner | J20: =IFERROR(_xludf.MAXIFS(ATTENDANCE_LOG!F:F, ATTENDANCE_LOG!C:C, A20&"", ATTENDANCE_LOG!G:G, "Present"), "") | K20: =IF(J20="", "", IFERROR(TODAY()-DATEVALUE(LEFT(J20,10)), "")) | L20: =IF(AND(ISNUMBER(K20), K20>=30), "⚠ Possibly Dropped", "") | R20: 247309 | S20: High workload / Can't arrange time | T20: High workload | U20: =IFERROR(__xludf.DUMMYFUNCTION("arrayformula(vlookup(to_text(R20),to_text($A$4:$B1010),2,0))"),"#N/A") -> #N/A | V20: Learning goal achieved
A21: 247026 | B21: ĐỖ HOÀNG MINH HUY | C21: =IFERROR(__xludf.DUMMYFUNCTION("arrayformula(VLOOKUP(to_Text(A21),to_Text(sheet2!$A$1:M1002),13,0))"),"LBU") -> LBU | D21: =IFERROR(__xludf.DUMMYFUNCTION("arrayformula(VLOOKUP(to_Text(A21),to_Text(sheet2!$A$1:M1002),12,0))"),"GSD") -> GSD | E21: Inactive | F21: {=IFERROR( INDEX(ATTENDANCE_INPUT!D:D, MATCH(1, (ATTENDANCE_INPUT!A:A=A21) * (ATTENDANCE_INPUT!V:V=_xludf.MAXIFS(ATTENDANCE_INPUT!V:V, ATTENDANCE_INPUT!A:A, A21)), 0)), "")} | G21: {=IFERROR( INDEX(ATTENDANCE_INPUT!E:E, MATCH(1, (ATTENDANCE_INPUT!A:A=A21) * (ATTENDANCE_INPUT!V:V=_xludf.MAXIFS(ATTENDANCE_INPUT!V:V, ATTENDANCE_INPUT!A:A, A21)), 0)), "")} | H21: {=IF(ISNA(MATCH(A21,sheet2!A:A,0)),"⏳ Chưa test",IFERROR(INDEX(LEVEL_HELPER!A:A,MATCH(INDEX(sheet2!N:N,MATCH(A21,sheet2!A:A,0)),LEVEL_HELPER!B:B,0)),"⏳ Chưa test"))} -> Pre-Intermediate | I21: {=IF(ISNA(MATCH(A21,sheet2!A:A,0)),H21,IF(INDEX(sheet2!O:O,MATCH(A21,sheet2!A:A,0))>0,IFERROR(INDEX(LEVEL_HELPER!A:A,MATCH(INDEX(sheet2!O:O,MATCH(A21,sheet2!A:A,0)),LEVEL_HELPER!B:B,0)),H21),H21))} -> Pre-Intermediate | J21: =IFERROR(_xludf.MAXIFS(ATTENDANCE_LOG!F:F, ATTENDANCE_LOG!C:C, A21&"", ATTENDANCE_LOG!G:G, "Present"), "") | K21: =IF(J21="", "", IFERROR(TODAY()-DATEVALUE(LEFT(J21,10)), "")) | L21: =IF(AND(ISNUMBER(K21), K21>=30), "⚠ Possibly Dropped", "") | M21: Completed (no continuation) | N21: Learning goal achieved | R21: 237004 | S21: Attend English center / 1-1 course | T21: Prefer other learning methods | U21: #N/A
A22: 237239 | B22: ĐỖ NGỌC THÀNH | C22: =IFERROR(__xludf.DUMMYFUNCTION("arrayformula(VLOOKUP(to_Text(A22),to_Text(sheet2!$A$1:M1002),13,0))"),"CHORUS") -> CHORUS | D22: =IFERROR(__xludf.DUMMYFUNCTION("arrayformula(VLOOKUP(to_Text(A22),to_Text(sheet2!$A$1:M1002),12,0))"),"DEV") -> DEV | E22: =IF(L22="⚠ Possibly Dropped","Inactive","Active") -> Active | F22: {=IFERROR( INDEX(ATTENDANCE_INPUT!D:D, MATCH(1, (ATTENDANCE_INPUT!A:A=A22) * (ATTENDANCE_INPUT!V:V=_xludf.MAXIFS(ATTENDANCE_INPUT!V:V, ATTENDANCE_INPUT!A:A, A22)), 0)), "")} | G22: {=IFERROR( INDEX(ATTENDANCE_INPUT!E:E, MATCH(1, (ATTENDANCE_INPUT!A:A=A22) * (ATTENDANCE_INPUT!V:V=_xludf.MAXIFS(ATTENDANCE_INPUT!V:V, ATTENDANCE_INPUT!A:A, A22)), 0)), "")} | H22: {=IF(ISNA(MATCH(A22,sheet2!A:A,0)),"⏳ Chưa test",IFERROR(INDEX(LEVEL_HELPER!A:A,MATCH(INDEX(sheet2!N:N,MATCH(A22,sheet2!A:A,0)),LEVEL_HELPER!B:B,0)),"⏳ Chưa test"))} -> Foundation | I22: {=IF(ISNA(MATCH(A22,sheet2!A:A,0)),H22,IF(INDEX(sheet2!O:O,MATCH(A22,sheet2!A:A,0))>0,IFERROR(INDEX(LEVEL_HELPER!A:A,MATCH(INDEX(sheet2!O:O,MATCH(A22,sheet2!A:A,0)),LEVEL_HELPER!B:B,0)),H22),H22))} -> Foundation | J22: =IFERROR(_xludf.MAXIFS(ATTENDANCE_LOG!F:F, ATTENDANCE_LOG!C:C, A22&"", ATTENDANCE_LOG!G:G, "Present"), "") | K22: =IF(J22="", "", IFERROR(TODAY()-DATEVALUE(LEFT(J22,10)), "")) | L22: =IF(AND(ISNUMBER(K22), K22>=30), "⚠ Possibly Dropped", "")
A23: 237006 | B23: ĐỖ THANH TÙNG | C23: =IFERROR(__xludf.DUMMYFUNCTION("arrayformula(VLOOKUP(to_Text(A23),to_Text(sheet2!$A$1:M1002),13,0))"),"CHORUS") -> CHORUS | D23: =IFERROR(__xludf.DUMMYFUNCTION("arrayformula(VLOOKUP(to_Text(A23),to_Text(sheet2!$A$1:M1002),12,0))"),"QC") -> QC | E23: Inactive | F23: {=IFERROR( INDEX(ATTENDANCE_INPUT!D:D, MATCH(1, (ATTENDANCE_INPUT!A:A=A23) * (ATTENDANCE_INPUT!V:V=_xludf.MAXIFS(ATTENDANCE_INPUT!V:V, ATTENDANCE_INPUT!A:A, A23)), 0)), "")} | G23: {=IFERROR( INDEX(ATTENDANCE_INPUT!E:E, MATCH(1, (ATTENDANCE_INPUT!A:A=A23) * (ATTENDANCE_INPUT!V:V=_xludf.MAXIFS(ATTENDANCE_INPUT!V:V, ATTENDANCE_INPUT!A:A, A23)), 0)), "")} | H23: {=IF(ISNA(MATCH(A23,sheet2!A:A,0)),"⏳ Chưa test",IFERROR(INDEX(LEVEL_HELPER!A:A,MATCH(INDEX(sheet2!N:N,MATCH(A23,sheet2!A:A,0)),LEVEL_HELPER!B:B,0)),"⏳ Chưa test"))} -> Beginner | I23: {=IF(ISNA(MATCH(A23,sheet2!A:A,0)),H23,IF(INDEX(sheet2!O:O,MATCH(A23,sheet2!A:A,0))>0,IFERROR(INDEX(LEVEL_HELPER!A:A,MATCH(INDEX(sheet2!O:O,MATCH(A23,sheet2!A:A,0)),LEVEL_HELPER!B:B,0)),H23),H23))} -> Beginner | J23: =IFERROR(_xludf.MAXIFS(ATTENDANCE_LOG!F:F, ATTENDANCE_LOG!C:C, A23&"", ATTENDANCE_LOG!G:G, "Present"), "") | K23: =IF(J23="", "", IFERROR(TODAY()-DATEVALUE(LEFT(J23,10)), "")) | L23: =IF(AND(ISNUMBER(K23), K23>=30), "⚠ Possibly Dropped", "") | M23: Completed (no continuation) | N23: High workload
A24: 227183 | B24: ĐỖ VŨ GIA LONG | C24: =IFERROR(__xludf.DUMMYFUNCTION("arrayformula(VLOOKUP(to_Text(A24),to_Text(sheet2!$A$1:M1002),13,0))"),"TBU") -> TBU | D24: =IFERROR(__xludf.DUMMYFUNCTION("arrayformula(VLOOKUP(to_Text(A24),to_Text(sheet2!$A$1:M1002),12,0))"),"DEV") -> DEV | E24: Waiting for class | F24: {=IFERROR( INDEX(ATTENDANCE_INPUT!D:D, MATCH(1, (ATTENDANCE_INPUT!A:A=A24) * (ATTENDANCE_INPUT!V:V=_xludf.MAXIFS(ATTENDANCE_INPUT!V:V, ATTENDANCE_INPUT!A:A, A24)), 0)), "")} | G24: {=IFERROR( INDEX(ATTENDANCE_INPUT!E:E, MATCH(1, (ATTENDANCE_INPUT!A:A=A24) * (ATTENDANCE_INPUT!V:V=_xludf.MAXIFS(ATTENDANCE_INPUT!V:V, ATTENDANCE_INPUT!A:A, A24)), 0)), "")} | H24: {=IF(ISNA(MATCH(A24,sheet2!A:A,0)),"⏳ Chưa test",IFERROR(INDEX(LEVEL_HELPER!A:A,MATCH(INDEX(sheet2!N:N,MATCH(A24,sheet2!A:A,0)),LEVEL_HELPER!B:B,0)),"⏳ Chưa test"))} -> ⏳ Chưa test | I24: {=IF(ISNA(MATCH(A24,sheet2!A:A,0)),H24,IF(INDEX(sheet2!O:O,MATCH(A24,sheet2!A:A,0))>0,IFERROR(INDEX(LEVEL_HELPER!A:A,MATCH(INDEX(sheet2!O:O,MATCH(A24,sheet2!A:A,0)),LEVEL_HELPER!B:B,0)),H24),H24))} -> ⏳ Chưa test | J24: =IFERROR(_xludf.MAXIFS(ATTENDANCE_LOG!F:F, ATTENDANCE_LOG!C:C, A24&"", ATTENDANCE_LOG!G:G, "Present"), "") | K24: =IF(J24="", "", IFERROR(TODAY()-DATEVALUE(LEFT(J24,10)), "")) | L24: =IF(AND(ISNUMBER(K24), K24>=30), "⚠ Possibly Dropped", "")
A25: 213835 | B25: ĐOÀN ANH MINH | C25: =IFERROR(__xludf.DUMMYFUNCTION("arrayformula(VLOOKUP(to_Text(A25),to_Text(sheet2!$A$1:M1002),13,0))"),"MOC") -> MOC | D25: =IFERROR(__xludf.DUMMYFUNCTION("arrayformula(VLOOKUP(to_Text(A25),to_Text(sheet2!$A$1:M1002),12,0))"),"DEV") -> DEV | E25: =IF(L25="⚠ Possibly Dropped","Inactive","Active") -> Active | F25: {=IFERROR( INDEX(ATTENDANCE_INPUT!D:D, MATCH(1, (ATTENDANCE_INPUT!A:A=A25) * (ATTENDANCE_INPUT!V:V=_xludf.MAXIFS(ATTENDANCE_INPUT!V:V, ATTENDANCE_INPUT!A:A, A25)), 0)), "")} | G25: {=IFERROR( INDEX(ATTENDANCE_INPUT!E:E, MATCH(1, (ATTENDANCE_INPUT!A:A=A25) * (ATTENDANCE_INPUT!V:V=_xludf.MAXIFS(ATTENDANCE_INPUT!V:V, ATTENDANCE_INPUT!A:A, A25)), 0)), "")} | H25: {=IF(ISNA(MATCH(A25,sheet2!A:A,0)),"⏳ Chưa test",IFERROR(INDEX(LEVEL_HELPER!A:A,MATCH(INDEX(sheet2!N:N,MATCH(A25,sheet2!A:A,0)),LEVEL_HELPER!B:B,0)),"⏳ Chưa test"))} -> Beginner | I25: {=IF(ISNA(MATCH(A25,sheet2!A:A,0)),H25,IF(INDEX(sheet2!O:O,MATCH(A25,sheet2!A:A,0))>0,IFERROR(INDEX(LEVEL_HELPER!A:A,MATCH(INDEX(sheet2!O:O,MATCH(A25,sheet2!A:A,0)),LEVEL_HELPER!B:B,0)),H25),H25))} -> Beginner | J25: =IFERROR(_xludf.MAXIFS(ATTENDANCE_LOG!F:F, ATTENDANCE_LOG!C:C, A25&"", ATTENDANCE_LOG!G:G, "Present"), "") | K25: =IF(J25="", "", IFERROR(TODAY()-DATEVALUE(LEFT(J25,10)), "")) | L25: =IF(AND(ISNUMBER(K25), K25>=30), "⚠ Possibly Dropped", "") | R25: 193630 | S25: High workload / Can't arrange time | T25: High workload | U25: =IFERROR(__xludf.DUMMYFUNCTION("arrayformula(vlookup(to_text(R25),to_text($A$4:$B974),2,0))"),"#N/A") -> #N/A
A26: 247390 | B26: ĐOÀN KHÁNH NGUYÊN | C26: =IFERROR(__xludf.DUMMYFUNCTION("arrayformula(VLOOKUP(to_Text(A26),to_Text(sheet2!$A$1:M1002),13,0))"),"LBU") -> LBU | D26: =IFERROR(__xludf.DUMMYFUNCTION("arrayformula(VLOOKUP(to_Text(A26),to_Text(sheet2!$A$1:M1002),12,0))"),"QC") -> QC | E26: Inactive | F26: {=IFERROR( INDEX(ATTENDANCE_INPUT!D:D, MATCH(1, (ATTENDANCE_INPUT!A:A=A26) * (ATTENDANCE_INPUT!V:V=_xludf.MAXIFS(ATTENDANCE_INPUT!V:V, ATTENDANCE_INPUT!A:A, A26)), 0)), "")} | G26: {=IFERROR( INDEX(ATTENDANCE_INPUT!E:E, MATCH(1, (ATTENDANCE_INPUT!A:A=A26) * (ATTENDANCE_INPUT!V:V=_xludf.MAXIFS(ATTENDANCE_INPUT!V:V, ATTENDANCE_INPUT!A:A, A26)), 0)), "")} | H26: {=IF(ISNA(MATCH(A26,sheet2!A:A,0)),"⏳ Chưa test",IFERROR(INDEX(LEVEL_HELPER!A:A,MATCH(INDEX(sheet2!N:N,MATCH(A26,sheet2!A:A,0)),LEVEL_HELPER!B:B,0)),"⏳ Chưa test"))} -> ⏳ Chưa test | I26: {=IF(ISNA(MATCH(A26,sheet2!A:A,0)),H26,IF(INDEX(sheet2!O:O,MATCH(A26,sheet2!A:A,0))>0,IFERROR(INDEX(LEVEL_HELPER!A:A,MATCH(INDEX(sheet2!O:O,MATCH(A26,sheet2!A:A,0)),LEVEL_HELPER!B:B,0)),H26),H26))} -> ⏳ Chưa test | J26: =IFERROR(_xludf.MAXIFS(ATTENDANCE_LOG!F:F, ATTENDANCE_LOG!C:C, A26&"", ATTENDANCE_LOG!G:G, "Present"), "") | K26: =IF(J26="", "", IFERROR(TODAY()-DATEVALUE(LEFT(J26,10)), "")) | L26: =IF(AND(ISNUMBER(K26), K26>=30), "⚠ Possibly Dropped", "") | M26: Discontinued mid-course | N26: Maternity leave
A27: 237222 | B27: ĐOÀN NHẬT QUANG | C27: =IFERROR(__xludf.DUMMYFUNCTION("arrayformula(VLOOKUP(to_Text(A27),to_Text(sheet2!$A$1:M1002),13,0))"),"CHORUS") -> CHORUS | D27: =IFERROR(__xludf.DUMMYFUNCTION("arrayformula(VLOOKUP(to_Text(A27),to_Text(sheet2!$A$1:M1002),12,0))"),"TA") -> TA | E27: =IF(L27="⚠ Possibly Dropped","Inactive","Active") -> Active | F27: {=IFERROR( INDEX(ATTENDANCE_INPUT!D:D, MATCH(1, (ATTENDANCE_INPUT!A:A=A27) * (ATTENDANCE_INPUT!V:V=_xludf.MAXIFS(ATTENDANCE_INPUT!V:V, ATTENDANCE_INPUT!A:A, A27)), 0)), "")} | G27: {=IFERROR( INDEX(ATTENDANCE_INPUT!E:E, MATCH(1, (ATTENDANCE_INPUT!A:A=A27) * (ATTENDANCE_INPUT!V:V=_xludf.MAXIFS(ATTENDANCE_INPUT!V:V, ATTENDANCE_INPUT!A:A, A27)), 0)), "")} | H27: {=IF(ISNA(MATCH(A27,sheet2!A:A,0)),"⏳ Chưa test",IFERROR(INDEX(LEVEL_HELPER!A:A,MATCH(INDEX(sheet2!N:N,MATCH(A27,sheet2!A:A,0)),LEVEL_HELPER!B:B,0)),"⏳ Chưa test"))} -> Beginner | I27: {=IF(ISNA(MATCH(A27,sheet2!A:A,0)),H27,IF(INDEX(sheet2!O:O,MATCH(A27,sheet2!A:A,0))>0,IFERROR(INDEX(LEVEL_HELPER!A:A,MATCH(INDEX(sheet2!O:O,MATCH(A27,sheet2!A:A,0)),LEVEL_HELPER!B:B,0)),H27),H27))} -> Beginner | J27: =IFERROR(_xludf.MAXIFS(ATTENDANCE_LOG!F:F, ATTENDANCE_LOG!C:C, A27&"", ATTENDANCE_LOG!G:G, "Present"), "") | K27: =IF(J27="", "", IFERROR(TODAY()-DATEVALUE(LEFT(J27,10)), "")) | L27: =IF(AND(ISNUMBER(K27), K27>=30), "⚠ Possibly Dropped", "") | M27: Completed (no continuation) | N27: High workload
A28: 213954 | B28: ĐOÀN QUANG TUẤN | C28: =IFERROR(__xludf.DUMMYFUNCTION("arrayformula(VLOOKUP(to_Text(A28),to_Text(sheet2!$A$1:M1002),13,0))"),"LBU") -> LBU | D28: =IFERROR(__xludf.DUMMYFUNCTION("arrayformula(VLOOKUP(to_Text(A28),to_Text(sheet2!$A$1:M1002),12,0))"),"DEV") -> DEV | E28: Inactive | F28: {=IFERROR( INDEX(ATTENDANCE_INPUT!D:D, MATCH(1, (ATTENDANCE_INPUT!A:A=A28) * (ATTENDANCE_INPUT!V:V=_xludf.MAXIFS(ATTENDANCE_INPUT!V:V, ATTENDANCE_INPUT!A:A, A28)), 0)), "")} | G28: {=IFERROR( INDEX(ATTENDANCE_INPUT!E:E, MATCH(1, (ATTENDANCE_INPUT!A:A=A28) * (ATTENDANCE_INPUT!V:V=_xludf.MAXIFS(ATTENDANCE_INPUT!V:V, ATTENDANCE_INPUT!A:A, A28)), 0)), "")} | H28: {=IF(ISNA(MATCH(A28,sheet2!A:A,0)),"⏳ Chưa test",IFERROR(INDEX(LEVEL_HELPER!A:A,MATCH(INDEX(sheet2!N:N,MATCH(A28,sheet2!A:A,0)),LEVEL_HELPER!B:B,0)),"⏳ Chưa test"))} -> Beginner | I28: {=IF(ISNA(MATCH(A28,sheet2!A:A,0)),H28,IF(INDEX(sheet2!O:O,MATCH(A28,sheet2!A:A,0))>0,IFERROR(INDEX(LEVEL_HELPER!A:A,MATCH(INDEX(sheet2!O:O,MATCH(A28,sheet2!A:A,0)),LEVEL_HELPER!B:B,0)),H28),H28))} -> Beginner | J28: =IFERROR(_xludf.MAXIFS(ATTENDANCE_LOG!F:F, ATTENDANCE_LOG!C:C, A28&"", ATTENDANCE_LOG!G:G, "Present"), "") | K28: =IF(J28="", "", IFERROR(TODAY()-DATEVALUE(LEFT(J28,10)), "")) | L28: =IF(AND(ISNUMBER(K28), K28>=30), "⚠ Possibly Dropped", "") | M28: Completed (no continuation) | N28: Learning goal achieved
A29: 183332 | B29: ĐOÀN QUỐC HẢI | C29: =IFERROR(__xludf.DUMMYFUNCTION("arrayformula(VLOOKUP(to_Text(A29),to_Text(sheet2!$A$1:M1002),13,0))"),"CHORUS") -> CHORUS | D29: =IFERROR(__xludf.DUMMYFUNCTION("arrayformula(VLOOKUP(to_Text(A29),to_Text(sheet2!$A$1:M1002),12,0))"),"DEV") -> DEV | E29: =IF(L29="⚠ Possibly Dropped","Inactive","Active") -> Active | F29: {=IFERROR( INDEX(ATTENDANCE_INPUT!D:D, MATCH(1, (ATTENDANCE_INPUT!A:A=A29) * (ATTENDANCE_INPUT!V:V=_xludf.MAXIFS(ATTENDANCE_INPUT!V:V, ATTENDANCE_INPUT!A:A, A29)), 0)), "")} | G29: {=IFERROR( INDEX(ATTENDANCE_INPUT!E:E, MATCH(1, (ATTENDANCE_INPUT!A:A=A29) * (ATTENDANCE_INPUT!V:V=_xludf.MAXIFS(ATTENDANCE_INPUT!V:V, ATTENDANCE_INPUT!A:A, A29)), 0)), "")} | H29: {=IF(ISNA(MATCH(A29,sheet2!A:A,0)),"⏳ Chưa test",IFERROR(INDEX(LEVEL_HELPER!A:A,MATCH(INDEX(sheet2!N:N,MATCH(A29,sheet2!A:A,0)),LEVEL_HELPER!B:B,0)),"⏳ Chưa test"))} -> Beginner | I29: {=IF(ISNA(MATCH(A29,sheet2!A:A,0)),H29,IF(INDEX(sheet2!O:O,MATCH(A29,sheet2!A:A,0))>0,IFERROR(INDEX(LEVEL_HELPER!A:A,MATCH(INDEX(sheet2!O:O,MATCH(A29,sheet2!A:A,0)),LEVEL_HELPER!B:B,0)),H29),H29))} -> Beginner | J29: =IFERROR(_xludf.MAXIFS(ATTENDANCE_LOG!F:F, ATTENDANCE_LOG!C:C, A29&"", ATTENDANCE_LOG!G:G, "Present"), "") | K29: =IF(J29="", "", IFERROR(TODAY()-DATEVALUE(LEFT(J29,10)), "")) | L29: =IF(AND(ISNUMBER(K29), K29>=30), "⚠ Possibly Dropped", "") | M29: Discontinued mid-course | N29: Team restructuring
A30: 247196 | B30: ĐOÀN TRẦN BÁ ĐẠT | C30: =IFERROR(__xludf.DUMMYFUNCTION("arrayformula(VLOOKUP(to_Text(A30),to_Text(sheet2!$A$1:M1002),13,0))"),"CHORUS") -> CHORUS | D30: =IFERROR(__xludf.DUMMYFUNCTION("arrayformula(VLOOKUP(to_Text(A30),to_Text(sheet2!$A$1:M1002),12,0))"),"DEV") -> DEV | E30: Inactive | F30: {=IFERROR( INDEX(ATTENDANCE_INPUT!D:D, MATCH(1, (ATTENDANCE_INPUT!A:A=A30) * (ATTENDANCE_INPUT!V:V=_xludf.MAXIFS(ATTENDANCE_INPUT!V:V, ATTENDANCE_INPUT!A:A, A30)), 0)), "")} | G30: {=IFERROR( INDEX(ATTENDANCE_INPUT!E:E, MATCH(1, (ATTENDANCE_INPUT!A:A=A30) * (ATTENDANCE_INPUT!V:V=_xludf.MAXIFS(ATTENDANCE_INPUT!V:V, ATTENDANCE_INPUT!A:A, A30)), 0)), "")} | H30: {=IF(ISNA(MATCH(A30,sheet2!A:A,0)),"⏳ Chưa test",IFERROR(INDEX(LEVEL_HELPER!A:A,MATCH(INDEX(sheet2!N:N,MATCH(A30,sheet2!A:A,0)),LEVEL_HELPER!B:B,0)),"⏳ Chưa test"))} -> Beginner | I30: {=IF(ISNA(MATCH(A30,sheet2!A:A,0)),H30,IF(INDEX(sheet2!O:O,MATCH(A30,sheet2!A:A,0))>0,IFERROR(INDEX(LEVEL_HELPER!A:A,MATCH(INDEX(sheet2!O:O,MATCH(A30,sheet2!A:A,0)),LEVEL_HELPER!B:B,0)),H30),H30))} -> Beginner | J30: =IFERROR(_xludf.MAXIFS(ATTENDANCE_LOG!F:F, ATTENDANCE_LOG!C:C, A30&"", ATTENDANCE_LOG!G:G, "Present"), "") | K30: =IF(J30="", "", IFERROR(TODAY()-DATEVALUE(LEFT(J30,10)), "")) | L30: =IF(AND(ISNUMBER(K30), K30>=30), "⚠ Possibly Dropped", "") | M30: Completed (no continuation) | N30: High workload | R30: 247141 | S30: Ungroup team | T30: Team restructuring | U30: #N/A
A31: 237227 | B31: DƯƠNG HOÀNG LONG | C31: =IFERROR(__xludf.DUMMYFUNCTION("arrayformula(VLOOKUP(to_Text(A31),to_Text(sheet2!$A$1:M1002),13,0))"),"TBU") -> TBU | D31: =IFERROR(__xludf.DUMMYFUNCTION("arrayformula(VLOOKUP(to_Text(A31),to_Text(sheet2!$A$1:M1002),12,0))"),"DEV") -> DEV | E31: =IF(L31="⚠ Possibly Dropped","Inactive","Active") -> Active | F31: {=IFERROR( INDEX(ATTENDANCE_INPUT!D:D, MATCH(1, (ATTENDANCE_INPUT!A:A=A31) * (ATTENDANCE_INPUT!V:V=_xludf.MAXIFS(ATTENDANCE_INPUT!V:V, ATTENDANCE_INPUT!A:A, A31)), 0)), "")} | G31: {=IFERROR( INDEX(ATTENDANCE_INPUT!E:E, MATCH(1, (ATTENDANCE_INPUT!A:A=A31) * (ATTENDANCE_INPUT!V:V=_xludf.MAXIFS(ATTENDANCE_INPUT!V:V, ATTENDANCE_INPUT!A:A, A31)), 0)), "")} | H31: {=IF(ISNA(MATCH(A31,sheet2!A:A,0)),"⏳ Chưa test",IFERROR(INDEX(LEVEL_HELPER!A:A,MATCH(INDEX(sheet2!N:N,MATCH(A31,sheet2!A:A,0)),LEVEL_HELPER!B:B,0)),"⏳ Chưa test"))} -> Pre-Intermediate | I31: {=IF(ISNA(MATCH(A31,sheet2!A:A,0)),H31,IF(INDEX(sheet2!O:O,MATCH(A31,sheet2!A:A,0))>0,IFERROR(INDEX(LEVEL_HELPER!A:A,MATCH(INDEX(sheet2!O:O,MATCH(A31,sheet2!A:A,0)),LEVEL_HELPER!B:B,0)),H31),H31))} -> Pre-Intermediate | J31: =IFERROR(_xludf.MAXIFS(ATTENDANCE_LOG!F:F, ATTENDANCE_LOG!C:C, A31&"", ATTENDANCE_LOG!G:G, "Present"), "") | K31: =IF(J31="", "", IFERROR(TODAY()-DATEVALUE(LEFT(J31,10)), "")) | L31: =IF(AND(ISNUMBER(K31), K31>=30), "⚠ Possibly Dropped", "") | M31: Discontinued mid-course | N31: High workload
A32: 247230 | B32: DƯƠNG LÊ XUÂN KHANG | C32: =IFERROR(__xludf.DUMMYFUNCTION("arrayformula(VLOOKUP(to_Text(A32),to_Text(sheet2!$A$1:M1002),13,0))"),"CHORUS") -> CHORUS | D32: =IFERROR(__xludf.DUMMYFUNCTION("arrayformula(VLOOKUP(to_Text(A32),to_Text(sheet2!$A$1:M1002),12,0))"),"DEV") -> DEV | E32: Inactive | F32: {=IFERROR( INDEX(ATTENDANCE_INPUT!D:D, MATCH(1, (ATTENDANCE_INPUT!A:A=A32) * (ATTENDANCE_INPUT!V:V=_xludf.MAXIFS(ATTENDANCE_INPUT!V:V, ATTENDANCE_INPUT!A:A, A32)), 0)), "")} | G32: {=IFERROR( INDEX(ATTENDANCE_INPUT!E:E, MATCH(1, (ATTENDANCE_INPUT!A:A=A32) * (ATTENDANCE_INPUT!V:V=_xludf.MAXIFS(ATTENDANCE_INPUT!V:V, ATTENDANCE_INPUT!A:A, A32)), 0)), "")} | H32: {=IF(ISNA(MATCH(A32,sheet2!A:A,0)),"⏳ Chưa test",IFERROR(INDEX(LEVEL_HELPER!A:A,MATCH(INDEX(sheet2!N:N,MATCH(A32,sheet2!A:A,0)),LEVEL_HELPER!B:B,0)),"⏳ Chưa test"))} -> Pre-Intermediate | I32: {=IF(ISNA(MATCH(A32,sheet2!A:A,0)),H32,IF(INDEX(sheet2!O:O,MATCH(A32,sheet2!A:A,0))>0,IFERROR(INDEX(LEVEL_HELPER!A:A,MATCH(INDEX(sheet2!O:O,MATCH(A32,sheet2!A:A,0)),LEVEL_HELPER!B:B,0)),H32),H32))} -> Pre-Intermediate | J32: =IFERROR(_xludf.MAXIFS(ATTENDANCE_LOG!F:F, ATTENDANCE_LOG!C:C, A32&"", ATTENDANCE_LOG!G:G, "Present"), "") | K32: =IF(J32="", "", IFERROR(TODAY()-DATEVALUE(LEFT(J32,10)), "")) | L32: =IF(AND(ISNUMBER(K32), K32>=30), "⚠ Possibly Dropped", "") | M32: Completed (no continuation) | N32: Learning goal achieved
A33: 193579 | B33: ĐƯỜNG QUANG HUY | C33: =IFERROR(__xludf.DUMMYFUNCTION("arrayformula(VLOOKUP(to_Text(A33),to_Text(sheet2!$A$1:M1002),13,0))"),"TBU") -> TBU | D33: =IFERROR(__xludf.DUMMYFUNCTION("arrayformula(VLOOKUP(to_Text(A33),to_Text(sheet2!$A$1:M1002),12,0))"),"DEV") -> DEV | E33: Inactive | F33: {=IFERROR( INDEX(ATTENDANCE_INPUT!D:D, MATCH(1, (ATTENDANCE_INPUT!A:A=A33) * (ATTENDANCE_INPUT!V:V=_xludf.MAXIFS(ATTENDANCE_INPUT!V:V, ATTENDANCE_INPUT!A:A, A33)), 0)), "")} | G33: {=IFERROR( INDEX(ATTENDANCE_INPUT!E:E, MATCH(1, (ATTENDANCE_INPUT!A:A=A33) * (ATTENDANCE_INPUT!V:V=_xludf.MAXIFS(ATTENDANCE_INPUT!V:V, ATTENDANCE_INPUT!A:A, A33)), 0)), "")} | H33: {=IF(ISNA(MATCH(A33,sheet2!A:A,0)),"⏳ Chưa test",IFERROR(INDEX(LEVEL_HELPER!A:A,MATCH(INDEX(sheet2!N:N,MATCH(A33,sheet2!A:A,0)),LEVEL_HELPER!B:B,0)),"⏳ Chưa test"))} -> Intermediate | I33: {=IF(ISNA(MATCH(A33,sheet2!A:A,0)),H33,IF(INDEX(sheet2!O:O,MATCH(A33,sheet2!A:A,0))>0,IFERROR(INDEX(LEVEL_HELPER!A:A,MATCH(INDEX(sheet2!O:O,MATCH(A33,sheet2!A:A,0)),LEVEL_HELPER!B:B,0)),H33),H33))} -> Intermediate | J33: =IFERROR(_xludf.MAXIFS(ATTENDANCE_LOG!F:F, ATTENDANCE_LOG!C:C, A33&"", ATTENDANCE_LOG!G:G, "Present"), "") | K33: =IF(J33="", "", IFERROR(TODAY()-DATEVALUE(LEFT(J33,10)), "")) | L33: =IF(AND(ISNUMBER(K33), K33>=30), "⚠ Possibly Dropped", "") | M33: Discontinued mid-course | N33: High workload
A34: 242009 | B34: DƯƠNG THỊ HƯƠNG LAN | C34: =IFERROR(__xludf.DUMMYFUNCTION("arrayformula(VLOOKUP(to_Text(A34),to_Text(sheet2!$A$1:M1002),13,0))"),"LBU") -> LBU | D34: =IFERROR(__xludf.DUMMYFUNCTION("arrayformula(VLOOKUP(to_Text(A34),to_Text(sheet2!$A$1:M1002),12,0))"),"HR") -> HR | E34: Inactive | F34: {=IFERROR( INDEX(ATTENDANCE_INPUT!D:D, MATCH(1, (ATTENDANCE_INPUT!A:A=A34) * (ATTENDANCE_INPUT!V:V=_xludf.MAXIFS(ATTENDANCE_INPUT!V:V, ATTENDANCE_INPUT!A:A, A34)), 0)), "")} | G34: {=IFERROR( INDEX(ATTENDANCE_INPUT!E:E, MATCH(1, (ATTENDANCE_INPUT!A:A=A34) * (ATTENDANCE_INPUT!V:V=_xludf.MAXIFS(ATTENDANCE_INPUT!V:V, ATTENDANCE_INPUT!A:A, A34)), 0)), "")} | H34: {=IF(ISNA(MATCH(A34,sheet2!A:A,0)),"⏳ Chưa test",IFERROR(INDEX(LEVEL_HELPER!A:A,MATCH(INDEX(sheet2!N:N,MATCH(A34,sheet2!A:A,0)),LEVEL_HELPER!B:B,0)),"⏳ Chưa test"))} -> ⏳ Chưa test | I34: {=IF(ISNA(MATCH(A34,sheet2!A:A,0)),H34,IF(INDEX(sheet2!O:O,MATCH(A34,sheet2!A:A,0))>0,IFERROR(INDEX(LEVEL_HELPER!A:A,MATCH(INDEX(sheet2!O:O,MATCH(A34,sheet2!A:A,0)),LEVEL_HELPER!B:B,0)),H34),H34))} -> ⏳ Chưa test | J34: =IFERROR(_xludf.MAXIFS(ATTENDANCE_LOG!F:F, ATTENDANCE_LOG!C:C, A34&"", ATTENDANCE_LOG!G:G, "Present"), "") | K34: =IF(J34="", "", IFERROR(TODAY()-DATEVALUE(LEFT(J34,10)), "")) | L34: =IF(AND(ISNUMBER(K34), K34>=30), "⚠ Possibly Dropped", "") | M34: Completed (no continuation) | N34: Prefer different learning format
A35: 247063 | B35: GIANG KHIẾT ĐÌNH | C35: =IFERROR(__xludf.DUMMYFUNCTION("arrayformula(VLOOKUP(to_Text(A35),to_Text(sheet2!$A$1:M1002),13,0))"),"POC") -> POC | D35: =IFERROR(__xludf.DUMMYFUNCTION("arrayformula(VLOOKUP(to_Text(A35),to_Text(sheet2!$A$1:M1002),12,0))"),"GSD") -> GSD | E35: =IF(L35="⚠ Possibly Dropped","Inactive","Active") -> Active | F35: {=IFERROR( INDEX(ATTENDANCE_INPUT!D:D, MATCH(1, (ATTENDANCE_INPUT!A:A=A35) * (ATTENDANCE_INPUT!V:V=_xludf.MAXIFS(ATTENDANCE_INPUT!V:V, ATTENDANCE_INPUT!A:A, A35)), 0)), "")} | G35: {=IFERROR( INDEX(ATTENDANCE_INPUT!E:E, MATCH(1, (ATTENDANCE_INPUT!A:A=A35) * (ATTENDANCE_INPUT!V:V=_xludf.MAXIFS(ATTENDANCE_INPUT!V:V, ATTENDANCE_INPUT!A:A, A35)), 0)), "")} | H35: {=IF(ISNA(MATCH(A35,sheet2!A:A,0)),"⏳ Chưa test",IFERROR(INDEX(LEVEL_HELPER!A:A,MATCH(INDEX(sheet2!N:N,MATCH(A35,sheet2!A:A,0)),LEVEL_HELPER!B:B,0)),"⏳ Chưa test"))} -> Beginner | I35: {=IF(ISNA(MATCH(A35,sheet2!A:A,0)),H35,IF(INDEX(sheet2!O:O,MATCH(A35,sheet2!A:A,0))>0,IFERROR(INDEX(LEVEL_HELPER!A:A,MATCH(INDEX(sheet2!O:O,MATCH(A35,sheet2!A:A,0)),LEVEL_HELPER!B:B,0)),H35),H35))} -> Beginner | J35: =IFERROR(_xludf.MAXIFS(ATTENDANCE_LOG!F:F, ATTENDANCE_LOG!C:C, A35&"", ATTENDANCE_LOG!G:G, "Present"), "") | K35: =IF(J35="", "", IFERROR(TODAY()-DATEVALUE(LEFT(J35,10)), "")) | L35: =IF(AND(ISNUMBER(K35), K35>=30), "⚠ Possibly Dropped", "")
A36: 193588 | B36: HÀ TRẦN TUẤN ANH | C36: =IFERROR(__xludf.DUMMYFUNCTION("arrayformula(VLOOKUP(to_Text(A36),to_Text(sheet2!$A$1:M1002),13,0))"),"MOC") -> MOC | D36: =IFERROR(__xludf.DUMMYFUNCTION("arrayformula(VLOOKUP(to_Text(A36),to_Text(sheet2!$A$1:M1002),12,0))"),"DEV") -> DEV | E36: =IF(L36="⚠ Possibly Dropped","Inactive","Active") -> Active | F36: {=IFERROR( INDEX(ATTENDANCE_INPUT!D:D, MATCH(1, (ATTENDANCE_INPUT!A:A=A36) * (ATTENDANCE_INPUT!V:V=_xludf.MAXIFS(ATTENDANCE_INPUT!V:V, ATTENDANCE_INPUT!A:A, A36)), 0)), "")} | G36: {=IFERROR( INDEX(ATTENDANCE_INPUT!E:E, MATCH(1, (ATTENDANCE_INPUT!A:A=A36) * (ATTENDANCE_INPUT!V:V=_xludf.MAXIFS(ATTENDANCE_INPUT!V:V, ATTENDANCE_INPUT!A:A, A36)), 0)), "")} | H36: {=IF(ISNA(MATCH(A36,sheet2!A:A,0)),"⏳ Chưa test",IFERROR(INDEX(LEVEL_HELPER!A:A,MATCH(INDEX(sheet2!N:N,MATCH(A36,sheet2!A:A,0)),LEVEL_HELPER!B:B,0)),"⏳ Chưa test"))} -> Beginner | I36: {=IF(ISNA(MATCH(A36,sheet2!A:A,0)),H36,IF(INDEX(sheet2!O:O,MATCH(A36,sheet2!A:A,0))>0,IFERROR(INDEX(LEVEL_HELPER!A:A,MATCH(INDEX(sheet2!O:O,MATCH(A36,sheet2!A:A,0)),LEVEL_HELPER!B:B,0)),H36),H36))} -> Beginner | J36: =IFERROR(_xludf.MAXIFS(ATTENDANCE_LOG!F:F, ATTENDANCE_LOG!C:C, A36&"", ATTENDANCE_LOG!G:G, "Present"), "") | K36: =IF(J36="", "", IFERROR(TODAY()-DATEVALUE(LEFT(J36,10)), "")) | L36: =IF(AND(ISNUMBER(K36), K36>=30), "⚠ Possibly Dropped", "")
